Workbook
Name CargasSociales: 'ANALISIS DE PRECIOS UNITARIOS'!$E$22
Name Gastosgenerales: 'ANALISIS DE PRECIOS UNITARIOS'!$F$35
Name ImpuestosIT: 'ANALISIS DE PRECIOS UNITARIOS'!$F$39
Name Preciounitario: 'ANALISIS DE PRECIOS UNITARIOS'!$F$40
Name PreciounitarioOP01: 'ANALISIS DE PRECIOS UNITARIOS'!$F$40
Name PrecioUnitarioOP02: 'ANALISIS DE PRECIOS UNITARIOS'!$F$82
Name Subtotalmanodeobra: 'ANALISIS DE PRECIOS UNITARIOS'!$F$21
Name tem: 'ANALISIS DE PRECIOS UNITARIOS'!$F$74
Name tm: 'ANALISIS DE PRECIOS UNITARIOS'!$F$56
Name tmo: 'ANALISIS DE PRECIOS UNITARIOS'!$F$66
Name Totalequipomaquinariayherramientas: 'ANALISIS DE PRECIOS UNITARIOS'!$F$32
Name Totalmanodeobra: 'ANALISIS DE PRECIOS UNITARIOS'!$F$24
Name TotalMateriales: 'ANALISIS DE PRECIOS UNITARIOS'!$F$14
Name UNITARIOS: #REF!
Name Utilidad: 'ANALISIS DE PRECIOS UNITARIOS'!$F$37

Sheet PRESUPUESTO GENERAL 
A1: PRESUPUESTO GENERAL
A2: Ubicacion: La Paz | E2: FECHA | F2: 43952
A3: PROYECTO: | C3: Contratista:
A4: CONSTRUCCION VIVIENDA
A6: COD. | B6: ITEM | C6: UNID. | D6: CANTIDAD | E6: PRECIO UNITARIO [Bs.] | F6: PARCIAL [Bs.]
A7: MODULO I: OBRAS PRELIMINARES
A8: OP 01 | B8: INSTALACION DE FAENAS | C8: Glb | D8: =VLOOKUP(A8,'COMPUTOS METRICOS'!A2:K482,11,0) -> 1 | E8: =PreciounitarioOP01 -> 1979.58 | F8: =ROUND(PRODUCT(D8:E8),3) -> 1979.58
A9: OP 02 | B9: REPLANTEO | C9: m² | D9: =VLOOKUP(A9,'COMPUTOS METRICOS'!A2:K482,11,0) -> 162.64 | E9: =PrecioUnitarioOP02 -> 930.06 | F9: =ROUND(PRODUCT(D9:E9),3) -> 151264.96
A10: MODULO II: OBRA GRUESA
A11: OG 01 | B11: EXCAVACION EN SUELO SEMIDURO H=1.5M | C11: m³ | D11: =VLOOKUP(A11,'COMPUTOS METRICOS'!$A$2:$K$482,11,0) -> 59.1 | F11: =PRODUCT(D11:E11) -> 59.1
A12: OG 02 | B12: ZAPATA H° A° | C12: m³ | D12: =VLOOKUP(A12,'COMPUTOS METRICOS'!$A$2:$K$482,11,0) -> 25.06 | F12: =PRODUCT(D12:E12) -> 25.06
A13: OG 03 | B13: CIMIENTO DE HORMIGON CICLOPEO (50%PD) | C13: m³ | D13: =VLOOKUP(A13,'COMPUTOS METRICOS'!$A$2:$K$482,11,0) -> 9.92 | F13: =PRODUCT(D13:E13) -> 9.92
A14: OG 04 | B14: SOBRECIMIENTO DE HORMIGON CICLOPEO (50%PD) | C14: m³ | D14: =VLOOKUP(A14,'COMPUTOS METRICOS'!$A$2:$K$482,11,0) -> 6.11 | F14: =PRODUCT(D14:E14) -> 6.11
A15: OG 05 | B15: COLUMNA H° A° | C15: m³ | D15: =VLOOKUP(A15,'COMPUTOS METRICOS'!$A$2:$K$482,11,0) -> 5.98 | F15: =PRODUCT(D15:E15) -> 5.98
A16: OG 06 | B16: IMPERMEABILIZACION SOBRECIMIENTO C/CARTON ASFALTICO | C16: m² | D16: =VLOOKUP(A16,'COMPUTOS METRICOS'!$A$2:$K$482,11,0) -> 15.27 | F16: =PRODUCT(D16:E16) -> 15.27
A17: OG 07 | B17: MURO DE 6 HUECOS DE 20cm | C17: m² | D17: =VLOOKUP(A17,'COMPUTOS METRICOS'!$A$2:$K$482,11,0) -> 163.25 | F17: =PRODUCT(D17:E17) -> 163.25
A18: OG 08 | B18: MURO DE 6 HUECOS DE 15 cm | C18: m² | D18: =VLOOKUP(A18,'COMPUTOS METRICOS'!$A$2:$K$482,11,0) -> 117.24 | F18: =PRODUCT(D18:E18) -> 117.24
A19: OG 09 | B19: MURO de 6 HUECOS DE 10 cm | C19: m² | D19: =VLOOKUP(A19,'COMPUTOS METRICOS'!$A$2:$K$482,11,0) -> 23.55 | F19: =PRODUCT(D19:E19) -> 23.55
A20: OG 10 | B20: VIGA H° A° | C20: m³ | D20: =VLOOKUP(A20,'COMPUTOS METRICOS'!$A$2:$K$482,11,0) -> 11.94 | F20: =PRODUCT(D20:E20) -> 11.94
A21: OG 11 | B21: LOSA ALIVIANADA H°A° | C21: m² | D21: =VLOOKUP(A21,'COMPUTOS METRICOS'!$A$2:$K$482,11,0) -> 122.62 | F21: =PRODUCT(D21:E21) -> 122.62
A22: OG 12 | B22: ESCALERA H° A° | C22: m³ | D22: =VLOOKUP(A22,'COMPUTOS METRICOS'!$A$2:$K$482,11,0) -> 1.12 | F22: =PRODUCT(D22:E22) -> 1.12
... A24: OG 14 | B24: DINTEL H° A° | C24: m | D24: =VLOOKUP(A24,'COMPUTOS METRICOS'!$A$2:$K$482,11,0) -> 13.6 | F24: =PRODUCT(D24:E24) -> 13.6
A25: MODULO III: OBRA FINA
A26: OF 01 | B26: BOTAGUAS DE H° A° | C26: m | D26: =VLOOKUP(A26,'COMPUTOS METRICOS'!$A$2:$K$482,11,0) -> 33.2 | F26: =PRODUCT(D26:E26) -> 33.2
A27: OF 02 | B27: EMPEDRADO Y CONTRAPISO DE H° | C27: m² | D27: =VLOOKUP(A27,'COMPUTOS METRICOS'!$A$2:$K$482,11,0) -> 109.54 | F27: =PRODUCT(D27:E27) -> 109.54
A28: OF 03 | B28: CONTRAPISO DE CEMENTO S/LOSA | C28: m² | D28: =VLOOKUP(A28,'COMPUTOS METRICOS'!$A$2:$K$482,11,0) -> 109.54 | F28: =PRODUCT(D28:E28) -> 109.54
A29: OF 04 | B29: PISO DE CERAMICA NACIONAL | C29: m² | D29: =VLOOKUP(A29,'COMPUTOS METRICOS'!$A$2:$K$482,11,0) -> 22 | F29: =PRODUCT(D29:E29) -> 22
A30: OF 05 | B30: PISO FLOTANTE | C30: m² | D30: =VLOOKUP(A30,'COMPUTOS METRICOS'!$A$2:$K$482,11,0) -> 197.07 | F30: =PRODUCT(D30:E30) -> 197.07
A31: OF 06 | B31: REVESTIMIENTO CERAMICA | C31: m² | D31: =VLOOKUP(A31,'COMPUTOS METRICOS'!$A$2:$K$482,11,0) -> 39.13 | F31: =PRODUCT(D31:E31) -> 39.13
A32: OF 07 | B32: REVOQUE CIELO RASO | C32: m² | D32: =VLOOKUP(A32,'COMPUTOS METRICOS'!$A$2:$K$880,11,) -> 109.54 | F32: =PRODUCT(D32:E32) -> 109.54
A33: OF 08 | B33: REVOQUE CIELO RASO S/LOSA | C33: m² | D33: =VLOOKUP(A33,'COMPUTOS METRICOS'!$A$2:$K$880,11,) -> 109.54 | F33: =PRODUCT(D33:E33) -> 109.54
A34: OF 09 | B34: REVOQUE EXTERIOR DE CEMENTO | C34: m² | D34: =VLOOKUP(A34,'COMPUTOS METRICOS'!$A$2:$K$880,11,) -> 163.24 | F34: =PRODUCT(D34:E34) -> 163.24
A35: OF 10 | B35: REVOQUE INTERIOR DE YESO | C35: m² | D35: =VLOOKUP(A35,'COMPUTOS METRICOS'!$A$2:$K$880,11,) -> 334.45 | F35: =PRODUCT(D35:E35) -> 334.45
A36: OF 11 | B36: PUERTA INTERIOR DE MADERA | C36: pza | D36: =VLOOKUP(A36,'COMPUTOS METRICOS'!$A$2:$K$880,11,) -> 10 | F36: =PRODUCT(D36:E36) -> 10
A37: OF 12 | B37: PUERTA EXTERIOR DE MADERA | C37: pza | D37: =VLOOKUP(A37,'COMPUTOS METRICOS'!$A$2:$K$880,11,) -> 2 | F37: =PRODUCT(D37:E37) -> 2
A38: OF 13 | B38: VENTANA DE ALUMINIO | C38: m² | D38: =VLOOKUP(A38,'COMPUTOS METRICOS'!$A$2:$K$880,11,) -> 12.7 | F38: =PRODUCT(D38:E38) -> 12.7
A39: OF 14 | B39: ZOCALO DE CERAMICA | C39: m | D39: =VLOOKUP(A39,'COMPUTOS METRICOS'!$A$2:$K$880,11,) -> 19.32 | F39: =PRODUCT(D39:E39) -> 19.32
A40: OF 15 | B40: ZOCALO DE MADERA | C40: m | D40: =VLOOKUP(A40,'COMPUTOS METRICOS'!$A$2:$K$880,11,) -> 138.68 | F40: =PRODUCT(D40:E40) -> 138.68
A41: MODULO IV: OBRA INSTALACIONES HIDROSANITARIAS
A42: IHS 01 | B42: BAJANTE DE CALAMINA | C42: m | D42: =VLOOKUP(A42,'COMPUTOS METRICOS'!$A$2:$K$880,11,) -> 11.56 | F42: =PRODUCT(D42:E42) -> 11.56
...

Sheet COMPUTOS METRICOS
A1: PLANILLA DE COMPUTOS METRICOS
A2: COD. | B2: ITEM | C2: DESCRIPCION | D2: EJES | E2: UNID. | F2: N° DE ELEMENTOS | G2: DIMENSION | J2: PARCIAL | K2: TOTAL
G3: Largo (m) | H3: Ancho (m) | I3: Alto (m)
A4: ='PRESUPUESTO GENERAL '!A7:B7 -> MODULO I: OBRAS PRELIMINARES
A5: ='PRESUPUESTO GENERAL '!A8 -> OP 01 | B5: ='PRESUPUESTO GENERAL '!B8 -> INSTALACION DE FAENAS | E5: ='PRESUPUESTO GENERAL '!C8 -> Glb | K5: =ROUND(SUM(J6),2) -> 1
F6: 1 | J6: =ROUND(PRODUCT(F6:I6),2) -> 1
A7: ='PRESUPUESTO GENERAL '!A9 -> OP 02 | B7: ='PRESUPUESTO GENERAL '!B9 -> REPLANTEO | E7: ='PRESUPUESTO GENERAL '!C9 -> m² | K7: =ROUND(SUM(J8:J10),2) -> 162.64
C8: zapatas | D8: todas | F8: 16 | G8: 1.45 | H8: 1.45 | J8: =ROUND(PRODUCT(F8:I8),2) -> 33.64
C9: cimientos | D9: (1-4)(A-E) | F9: 1 | G9: 8 | H9: 12 | J9: =ROUND(PRODUCT(F9:I9),2) -> 96
D10: (4-6)(B-E) | F10: 1 | G10: 3 | H10: 11 | J10: =ROUND(PRODUCT(F10:I10),2) -> 33
A11: ='PRESUPUESTO GENERAL '!A10:B10 -> MODULO II: OBRA GRUESA
A12: ='PRESUPUESTO GENERAL '!A11 -> OG 01 | B12: ='PRESUPUESTO GENERAL '!B11 -> EXCAVACION EN SUELO SEMIDURO H=1.5M | E12: ='PRESUPUESTO GENERAL '!C11 -> m³ | K12: =ROUND(SUM(J13:J20),2) -> 59.1
C13: zapatas | D13: TODAS | F13: 16 | G13: 1.45 | H13: 1.45 | I13: 1.45 | J13: =ROUND(PRODUCT(F13:I13),2) -> 48.78
C14: cimientos | D14: 1,4(A-E) | F14: 2 | G14: 12 | H14: 0.3 | I14: 0.4 | J14: =ROUND(PRODUCT(F14:I14),2) -> 2.88
D15: 2,5(C-D) | F15: 2 | G15: 3 | H15: 0.3 | I15: 0.4 | J15: =ROUND(PRODUCT(F15:I15),2) -> 0.72
D16: 3(A-C) | F16: 1 | G16: 5 | H16: 0.3 | I16: 0.4 | J16: =ROUND(PRODUCT(F16:I16),2) -> 0.6
D17: 6(B-E) | F17: 1 | G17: 11 | H17: 0.3 | I17: 0.4 | J17: =ROUND(PRODUCT(F17:I17),2) -> 1.32
D18: A,C,E(1-4) | F18: 3 | G18: 8 | H18: 0.3 | I18: 0.4 | J18: =ROUND(PRODUCT(F18:I18),2) -> 2.88
D19: D(1-3) | F19: 1 | G19: 3.99 | H19: 0.3 | I19: 0.4 | J19: =ROUND(PRODUCT(F19:I19),2) -> 0.48
D20: B,C,D,E(4-6) | F20: 4 | G20: 3 | H20: 0.3 | I20: 0.4 | J20: =ROUND(PRODUCT(F20:I20),2) -> 1.44
A21: ='PRESUPUESTO GENERAL '!A12 -> OG 02 | B21: ='PRESUPUESTO GENERAL '!B12 -> ZAPATA H° A° | E21: ='PRESUPUESTO GENERAL '!C12 -> m³ | K21: =ROUND(SUM(J22),2) -> 25.06
C22: AREA DE ZAPATA | D22: TODAS | F22: 16 | G22: 1.566 | J22: =ROUND(PRODUCT(F22:I22),2) -> 25.06
A23: ='PRESUPUESTO GENERAL '!A13 -> OG 03 | B23: ='PRESUPUESTO GENERAL '!B13 -> CIMIENTO DE HORMIGON CICLOPEO (50%PD) | E23: ='PRESUPUESTO GENERAL '!C13 -> m³ | K23: =ROUND(SUM(J23:J31),2) -> 9.92
D24: 1,4(A-E) | F24: 2 | G24: 12 | H24: 0.3 | I24: 0.4 | J24: =ROUND(PRODUCT(F24:I24),2) -> 2.88
D25: 2,5(C-D) | F25: 2 | G25: 3 | H25: 0.3 | I25: 0.4 | J25: =ROUND(PRODUCT(F25:I25),2) -> 0.72
D26: 3(A-C) | F26: 1 | G26: 5 | H26: 0.3 | I26: 0.4 | J26: =ROUND(PRODUCT(F26:I26),2) -> 0.6
D27: 6(B-E) | F27: 1 | G27: 11 | H27: 0.3 | I27: 0.4 | J27: =ROUND(PRODUCT(F27:I27),2) -> 1.32
D28: A,C,E(1-4) | F28: 3 | G28: 8 | H28: 0.3 | I28: 0.4 | J28: =ROUND(PRODUCT(F28:I28),2) -> 2.88
D29: D(1-3) | F29: 1 | G29: 3.99 | H29: 0.3 | I29: 0.4 | J29: =ROUND(PRODUCT(F29:I29),2) -> 0.48
D30: B,C,D,E(4-6) | F30: 4 | G30: 3 | H30: 0.3 | I30: 0.4 | J30: =ROUND(PRODUCT(F30:I30),2) -> 1.44
C31: COLUMNAS | D31: TODAS | F31: -16 | G31: 0.25 | H31: 0.25 | I31: 0.4 | J31: =ROUND(PRODUCT(F31:I31),2) -> -0.4
A32: ='PRESUPUESTO GENERAL '!A14 -> OG 04 | B32: ='PRESUPUESTO GENERAL '!B14 -> SOBRECIMIENTO DE HORMIGON CICLOPEO (50%PD) | E32: ='PRESUPUESTO GENERAL '!C14 -> m³ | K32: =ROUND(SUM(J32:J44),2) -> 6.11
D33: 1(A-E) | F33: 1 | G33: 12.03 | H33: 0.2 | I33: 0.4 | J33: =ROUND(PRODUCT(F33:I33),2) -> 0.96
D34: 2,5(C-D) | F34: 2 | G34: 3 | H34: 0.2 | I34: 0.4 | J34: =ROUND(PRODUCT(F34:I34),2) -> 0.48
D35: 3,4(A-C) | F35: 2 | G35: 5 | H35: 0.2 | I35: 0.4 | J35: =ROUND(PRODUCT(F35:I35),2) -> 0.8
D36: 4(D-E) | F36: 1 | G36: 4.03 | H36: 0.2 | I36: 0.4 | J36: =ROUND(PRODUCT(F36:I36),2) -> 0.32
D37: 6(B-E) | F37: 1 | G37: 11.05 | H37: 0.2 | I37: 0.4 | J37: =ROUND(PRODUCT(F37:I37),2) -> 0.88
D38: A,C,E(1-4) | F38: 3 | G38: 8.03 | H38: 0.2 | I38: 0.4 | J38: =ROUND(PRODUCT(F38:I38),2) -> 1.93
D39: D(1-2) | F39: 1 | G39: 2.58 | H39: 0.2 | I39: 0.4 | J39: =ROUND(PRODUCT(F39:I39),2) -> 0.21
D40: B,C,D,E(4-6) | F40: 4 | G40: 3.03 | H40: 0.2 | I40: 0.4 | J40: =ROUND(PRODUCT(F40:I40),2) -> 0.97
...

Sheet ANALISIS DE PRECIOS UNITARIOS
A1: ANALISIS DE PRECIOS UNITARIOS
A3: PROYECTO | B3: =LOOKUP(A3,'PRESUPUESTO GENERAL '!$A$4) -> CONSTRUCCION VIVIENDA | E3: TOTAL U$D | F3: =PRODUCT(Preciounitario/F4) -> 284.42241
A4: CODIGO | B4: OP 01 | F4: 6.96
A5: ITEM | B5: =VLOOKUP(B4,Tabla1[#All],2,FALSE) -> INSTALACION DE FAENAS | E5: Computo de Obra | F5: =VLOOKUP(B4,Tabla1[#All],4,FALSE) -> 1
A6: UNIDAD | B6: =VLOOKUP(B4,Tabla1[#All],3,FALSE) -> Glb
A7: FECHA | B7: ='PRESUPUESTO GENERAL '!$F$2 -> 43952 | E7: TOTAL U$D | F7: =ROUND(PRODUCT(F3,F5),2) -> 284.42
A9: 1 | B9: MATERIALES
A10: COD | B10: DESCRIPCION | C10: UNID | D10: CANTIDAD | E10: PRECIO PRODUCTIVO | F10: TOTAL
A11: 1 | B11: =VLOOKUP(A11,InsumoMateriales[],2,FALSE) -> ACCESORIOS 5/8" | C11: =VLOOKUP(A11,InsumoMateriales[],3,FALSE) -> juego | D11: 1 | E11: =VLOOKUP(A11,InsumoMateriales[],4,FALSE) -> 2.75 | F11: =ROUND(PRODUCT(D11:E11),2) -> 2.75
F12: =ROUND(PRODUCT(D12:E12),2) -> 0
F13: =ROUND(PRODUCT(D13:E13),2) -> 0
A14: TOTAL MATERIALES | F14: =ROUND(SUM(F11:F13),2) -> 2.75
A16: 2 | B16: MANO DE OBRA
A17: COD | B17: DESCRIPCION | C17: UNID | D17: CANTIDAD | E17: PRECIO PRODUCTIVO | F17: TOTAL
A18: 1 | B18: =VLOOKUP(A18,INSUMOSMANODEOBRA[],2,FALSE) -> ALBAÑIL | C18: =VLOOKUP(A18,INSUMOSMANODEOBRA[],3,FALSE) -> hr | D18: 24 | E18: =VLOOKUP(A18,INSUMOSMANODEOBRA[],4,FALSE) -> 18.75 | F18: =ROUND(PRODUCT(D18:E18),2) -> 450
A19: 3 | B19: =VLOOKUP(A19,INSUMOSMANODEOBRA[],2,FALSE) -> AYUDANTE PLOMERO | C19: =VLOOKUP(A19,INSUMOSMANODEOBRA[],3,FALSE) -> hr | D19: 24 | E19: =VLOOKUP(A19,INSUMOSMANODEOBRA[],4,FALSE) -> 15 | F19: =ROUND(PRODUCT(D19:E19),2) -> 360
F20: =ROUND(PRODUCT(D20:E20),2) -> 0
A21: SUB TOTAL MANO DE OBRA | F21: =ROUND(SUM(F18:F20),2) -> 810
B22: CARGAS SOCIALES | D22: % | E22: 0.55 | F22: =ROUND(PRODUCT(Subtotalmanodeobra,CargasSociales),2) -> 445.5
B23: IMPUESTOS IVA | D23: % | E23: 0.1494 | F23: =ROUND(SUM(Subtotalmanodeobra,F22)*E23,2) -> 187.57
A24: TOTAL DE MANO DE OBRA | F24: =ROUND(SUM(Subtotalmanodeobra,F22,F23),2) -> 1443.07
A26: 3 | B26: EQUIPO, MAQUINARIA Y HERRAMIENTA
A27: COD | B27: DESCRIPCION | C27: UNID | D27: CANTIDAD | E27: PRECIO PRODUCTIVO | F27: TOTAL
F28: =ROUND(PRODUCT(D28:E28),2) -> 0
F29: =ROUND(PRODUCT(D29:E29),2) -> 0
F30: =ROUND(PRODUCT(D30:E30),2) -> 0
A31: HERRAMIENTAS MENORES TOTAL MANO DE OBRA | D31: % | E31: 0.05 | F31: =ROUND(PRODUCT(Totalmanodeobra,E31),2) -> 72.15
B32: TOTAL EQUIPO, MAQUINARIA Y HERRAMIENTAS | F32: =ROUND(SUM(F28:F31),2) -> 72.15
A34: 4 | B34: GASTOS GENERALES Y ADMINISTRATIVOS
C35: % | D35: 0.15 | E35: 1+2+3 | F35: =ROUND(SUM(TotalMateriales,Totalmanodeobra,Totalequipomaquinariayherramientas)*D35,2) -> 227.7
A36: 5 | B36: UTILIDAD
C37: % | D37: 0.1 | E37: 1+2+3+4 | F37: =ROUND(SUM(TotalMateriales,Totalmanodeobra,Totalequipomaquinariayherramientas,Gastosgenerales)*D37,2) -> 174.57
A38: 6 | B38: IMPUESTOS IT
C39: % | D39: 0.0309 | E39: 1+2+3+4+5 | F39: =ROUND(SUM(TotalMateriales,Totalmanodeobra,Totalequipomaquinariayherramientas,Gastosgenerales,Utilidad)*D39,2) -> 59.34
A40: PRECIO UNITARIO TOTAL | E40: 1+2+3+4+5+6 | F40: =ROUND(SUM(TotalMateriales,Totalmanodeobra,Totalequipomaquinariayherramientas,Gastosgenerales,Utilidad,ImpuestosIT),2) -> 1979.58
A42: ANALISIS DE PRECIOS UNITARIOS
A44: PROYECTO | B44: =LOOKUP(A44,'PRESUPUESTO GENERAL '!$A$4) -> CONSTRUCCION VIVIENDA | E44: TOTAL U$D | F44: =PRODUCT(Preciounitario/F45) -> 284.42241
A45: CODIGO | B45: OP 02 | F45: 6.96
A46: ITEM | B46: =VLOOKUP(B45,Tabla1[#All],2,FALSE) -> REPLANTEO | E46: Computo de Obra | F46: =VLOOKUP(B45,Tabla1[#All],4,FALSE) -> 162.64
A47: UNIDAD | B47: =VLOOKUP(B45,Tabla1[#All],3,FALSE) -> m²
...

Sheet ISUMOS MATERIALES
A1: INSUMO MATERIALES
A2: COD | B2: DESCRIPCION | C2: UNID | D2: PRECIO UNITARIO | E2: FECHA | F2: GRUPO | G2: PROVEEDORES | I2: PROVEEDORES | J2: Barraca San Pedro
A3: 1 | B3: ACCESORIOS 5/8" | C3: juego | D3: 2.75 | E3: 43953 | F3: ACCESORIOS ELECTRICO
A4: 2 | B4: ACCESORIOS F.G. D=1/2" IND. ARGEN. | C4: pza | D4: 5.8 | E4: 43953 | F4: ACCESORIOS | G4: Barraca San Pedro | I4: Suma de PRECIO UNITARIO | J4: Etiquetas de columna
A5: 3 | B5: ACCESORIOS PARA AUDIO | C5: juego | D5: 61.6 | E5: 43953 | F5: ACCESORIOS | G5: Ferreteria Lucas | I5: Etiquetas de fila | J5: pza | K5: Total general
A6: 4 | B6: ACCESORIOS PARA INSTALACION SANITARIA | C6: glb | D6: 23 | E6: 43953 | F6: ACCESORIOS SANITARIOS | G6: Señora Camila | I6: ACCESORIOS F.G. D=1/2" IND. ARGEN. | J6: 5.8 | K6: 5.8
A7: 5 | B7: ACCESORIOS PVC 2" ESQ 40 | C7: glb | D7: 28.1 | E7: 43953 | F7: ACCESORIOS PVC | G7: Ferreteria Lucas | I7: Total general | J7: 5.8 | K7: 5.8
A8: 6 | B8: AGUARRAS | C8: lt | D8: 11.78 | E8: 43953 | G8: Emisa
A9: 7 | B9: ALAMBRE DE AMARRE | C9: kg | D9: 6.8 | E9: 43953 | F9: ALAMBRE | G9: Ferreteria Obrajes
A10: 8 | B10: ALAMBRE TEJIDO | C10: m² | D10: 3 | E10: 43953 | F10: ALAMBRE | G10: Volqueta Demetrio
A11: 9 | B11: ALQUITRAN | C11: kg | D11: 13.8 | E11: 43953 | G11: Volqueta Primo
A12: 10 | B12: ARENA COMUN | C12: m³ | D12: 60 | E12: 43953 | F12: AGREGADOS | G12: Volqueta Primo
A13: 11 | B13: ARENA FINA | C13: m³ | D13: 71.1 | E13: 43953 | F13: AGREGADOS | G13: Volqueta Demetrio
A14: 12 | B14: BISAGRA DE 4" | C14: pza | D14: 5.6 | E14: 43953 | F14: QUINCALLERIA | G14: Volqueta Demetrio
A15: 13 | B15: CABLE AISLADO MONOPOLAR # 10 | C15: m | D15: 1.9 | E15: 43953 | F15: INSTALACION ELECTRICA | G15: Barraca Roma
A16: 14 | B16: CABLE AWG N14 | C16: m | D16: 5.8 | E16: 43953 | F16: INSTALACION ELECTRICA | G16: Barraca Roma
A17: 15 | B17: CABLE CU PARA TELEFONO 2X22 | C17: m | D17: 1.21 | E17: 43953 | F17: INSTALACION ELECTRICA | G17: Ferreteria Obrajes
A18: 16 | B18: CABLE DE CU AWG 20 TW | C18: m | D18: 1.76 | E18: 43953 | F18: INSTALACION ELECTRICA | G18: Distribuidora Monopol
A19: 17 | B19: CAJA PLASTICA CIRCULAR | C19: pza | D19: 5.72 | E19: 43953 | F19: INSTALACION ELECTRICA | G19: Distribuidora Monopol
A20: 18 | B20: CAJA PLASTICA RECTANGULAR | C20: pza | D20: 5.39 | E20: 43953 | F20: INSTALACION ELECTRICA
A21: 19 | B21: CAJA PLASTICA | C21: pza | D21: 1.1 | E21: 43953 | F21: INSTALACION ELECTRICA
A22: 20 | B22: CAL | C22: kg | D22: 0.4 | E22: 43953
A23: 21 | B23: CALAMINA ONDULADA # 28 | C23: m² | D23: 50.2 | E23: 43953 | F23: CALAMINA
A24: 22 | B24: CALAMINA PLANA # 26 | C24: m² | D24: 25.2 | E24: 43953 | F24: CALAMINA
A25: 23 | B25: CALAMINA PLANA # 28 | C25: m² | D25: 26.4 | E25: 43953 | F25: CALAMINA
A26: 24 | B26: CARTON ASFALTICO | C26: m² | D26: 28.8 | E26: 43953
A27: 25 | B27: CEMENTO BLANCO IMPORTADO | C27: kg | D27: 0.9 | E27: 43953 | F27: CEMENTO
A28: 26 | B28: CEMENTO BLANCO | C28: kg | D28: 3.7 | E28: 43953 | F28: CEMENTO
A29: 27 | B29: CEMENTO COLA | C29: kg | D29: 1.1 | E29: 43953 | F29: CEMENTO
A30: 28 | B30: CEMENTO PORTLAND VIACHA | C30: kg | D30: 1.06 | E30: 43953 | F30: CEMENTO
A31: 29 | B31: CEMENTO PORTLAND | C31: kg | D31: 1 | E31: 43953 | F31: CEMENTO
A32: 30 | B32: CERAMICA ESMALTADA NAL. 20*30 | C32: m² | D32: 54 | E32: 43953 | F32: CERAMICA
A33: 31 | B33: CHICOTILLO METALICO (45 CM.) | C33: pza | D33: 3.6 | E33: 43953 | F33: CHICOTILLO
A34: 32 | B34: CHICOTILLO | C34: pza | D34: 19.5 | E34: 43953 | F34: CHICOTILLO
A35: 33 | B35: CINTA AISLANTE | C35: rollo | D35: 3.7 | E35: 43953 | F35: CINTA
A36: 34 | B36: CLAVOS PARA CALAMINA | C36: kg | D36: 13.8 | E36: 43953 | F36: CLAVOS
A37: 35 | B37: CLAVOS | C37: kg | D37: 7 | E37: 43953 | F37: CLAVOS
A38: 36 | B38: COLA FRESCA | C38: kg | D38: 6.4 | E38: 43953 | F38: COLA
... A101: 99 | B101: ZOCALO MARA DE 3" | C101: m | D101: 7.5 | E101: 43953 | F101: ZOCALO

Sheet lista de proveedores 
J2: PROVEEDORES | K2: Barraca San Pedro
A3: cod | B3: PROVEEDORES | C3: DIRECCION | D3: TELEFONO | E3: CORREO
A4: 1 | B4: Barraca San Pedro | C4: OBRAJES | D4: 711552 | E4: barraca@gmail.com | J4: Suma de PRECIO UNITARIO | K4: Etiquetas de columna
A5: 2 | B5: Volqueta Primo | C5: llojeta | D5: 125222 | J5: Etiquetas de fila | K5: OBRAJES | L5: Total general
A6: 3 | B6: Volqueta Primo | C6: llojeta | D6: 55552221 | J6: (en blanco) | K6: 4873.58 | L6: 4873.58
A7: 4 | B7: Volqueta Demetrio | C7: llojeta | D7: 121255 | J7: ACCESORIOS 5/8" | K7: 2.75 | L7: 2.75
A8: 5 | B8: Volqueta Demetrio | C8: llojeta | D8: 111452 | J8: 711552 | K8: 2.75 | L8: 2.75
A9: 6 | B9: Barraca Roma | C9: SUD | D9: 1155 | J9: CAJA PLASTICA | K9: 1.1 | L9: 1.1
A10: 7 | B10: Barraca Roma | D10: 55221 | J10: 711552 | K10: 1.1 | L10: 1.1
A11: 8 | B11: Ferreteria Obrajes | C11: OBRAJES | D11: 254110 | J11: CAJA PLASTICA RECTANGULAR | K11: 5.39 | L11: 5.39
A12: 9 | B12: Distribuidora Monopol | C12: ACHUMANI | D12: 111444 | J12: 711552 | K12: 5.39 | L12: 5.39
A13: 10 | B13: Distribuidora Monopol | C13: ACHUMANI | D13: 44522 | J13: CAL | K13: 0.4 | L13: 0.4
A14: 11 | B14: Ferreterias San Juan | C14: La Paz | D14: 165461 | J14: 711552 | K14: 0.4 | L14: 0.4
A15: 12 | B15: Barraca Aranjuez | C15: Mallasa | D15: 36523 | J15: CALAMINA ONDULADA # 28 | K15: 50.2 | L15: 50.2
A16: 13 | B16: Ferreteria Lucas | C16: SOPOCACHI | D16: 96322 | J16: 711552 | K16: 50.2 | L16: 50.2
A17: 14 | B17: Señora Camila | C17: ACHUMANI | D17: 225622 | J17: CALAMINA PLANA # 26 | K17: 25.2 | L17: 25.2
A18: 15 | B18: Ferreteria Lucas | C18: SOPOCACHI | D18: 525562 | J18: 711552 | K18: 25.2 | L18: 25.2
A19: 16 | B19: Emisa | C19: CENTRO | D19: 25550 | E19: emisa@hotmail.com | J19: CALAMINA PLANA # 28 | K19: 26.4 | L19: 26.4
A20: 17 | B20: Ferreteria Obrajes | C20: OBRAJES | D20: 115522 | J20: 711552 | K20: 26.4 | L20: 26.4
A21: 18 | B21: Volqueta Demetrio | C21: llojeta | D21: 14552 | J21: CARTON ASFALTICO | K21: 28.8 | L21: 28.8
A22: 19 | B22: Volqueta Demetrio | C22: llojeta | D22: 111452 | J22: 711552 | K22: 28.8 | L22: 28.8
A23: 20 | B23: Barraca Roma | C23: SUD | D23: 1155 | J23: CEMENTO BLANCO | K23: 3.7 | L23: 3.7
A24: 21 | B24: Barraca Roma | D24: 1114 | J24: 711552 | K24: 3.7 | L24: 3.7
A25: 22 | B25: Ferreteria Obrajes | C25: OBRAJES | D25: 1111552 | J25: CEMENTO BLANCO IMPORTADO | K25: 0.9 | L25: 0.9
A26: 23 | B26: Distribuidora Monopol | C26: ACHUMANI | D26: 111444 | J26: 711552 | K26: 0.9 | L26: 0.9
J27: CEMENTO COLA | K27: 1.1 | L27: 1.1
J28: 711552 | K28: 1.1 | L28: 1.1
J29: CEMENTO PORTLAND | K29: 1 | L29: 1
J30: 711552 | K30: 1 | L30: 1
J31: CEMENTO PORTLAND VIACHA | K31: 1.06 | L31: 1.06
J32: 711552 | K32: 1.06 | L32: 1.06
J33: CERAMICA ESMALTADA NAL. 20*30 | K33: 54 | L33: 54
J34: 711552 | K34: 54 | L34: 54
J35: CHICOTILLO | K35: 19.5 | L35: 19.5
J36: 711552 | K36: 19.5 | L36: 19.5
J37: CHICOTILLO METALICO (45 CM.) | K37: 3.6 | L37: 3.6
J38: 711552 | K38: 3.6 | L38: 3.6
J39: CINTA AISLANTE | K39: 3.7 | L39: 3.7
J40: 711552 | K40: 3.7 | L40: 3.7
J41: CLAVOS | K41: 7 | L41: 7
...

Sheet INSUMO MANO DE OBRA
A2: COD | B2: MANO DE OBRA | C2: UNID | D2: PRECIO UNITARIO | E2: FECHA | F2: JORNAL LA PAZ | G2: JORNAL ORURO
A3: 1 | B3: ALBAÑIL | C3: hr | D3: 18.75 | E3: 43953 | F3: 150 | G3: 150
A4: 2 | B4: ARMADOR | C4: hr | D4: 22.5 | E4: 43953 | F4: 180 | G4: 140
A5: 3 | B5: AYUDANTE PLOMERO | C5: hr | D5: 15 | E5: 43953 | F5: 120 | G5: 110
A6: 4 | B6: AYUDANTE | C6: hr | D6: 15 | E6: 43953 | F6: 120 | G6: 180
A7: 5 | B7: CARPINTERO | C7: hr | D7: 22.5 | E7: 43953 | F7: 180 | G7: 180
A8: 6 | B8: CONTRA MESTRO | C8: hr | D8: 18.75 | E8: 43953 | F8: 150
A9: 7 | B9: ELECTRICISTA | C9: hr | D9: 22.5 | E9: 43953 | F9: 180
A10: 8 | B10: ENCOFRADOR | C10: hr | D10: 22.5 | E10: 43953 | F10: 180
A11: 9 | B11: ENFERRADOR | C11: hr | D11: 22.5 | E11: 43953 | F11: 180
A12: 10 | B12: ESPECIALISTA CALIFICADO | C12: hr | D12: 25 | E12: 43953 | F12: 200
A13: 11 | B13: ESPECIALISTA PLOMERO | C13: hr | D13: 25 | E13: 43953 | F13: 200
A14: 12 | B14: ESPECIALISTA | C14: hr | D14: 25 | E14: 43953 | F14: 200
A15: 13 | B15: MAESTRO ALBAÑIL | C15: hr | D15: 22.5 | E15: 43953 | F15: 180
A16: 14 | B16: PEON | C16: hr | D16: 13.75 | E16: 43953 | F16: 110
A17: 15 | B17: PINTOR | C17: hr | D17: 18.75 | E17: 43953 | F17: 150
A18: 16 | B18: PLOMERO | C18: hr | D18: 18.75 | E18: 43953 | F18: 150

Sheet INSUMO EQUIPO Y MAQUINARIA
A2: COD | B2: MANO DE OBRA | C2: UNID | D2: PRECIO UNITARIO | E2: FECHA
A3: 1 | B3: EQUIPO TOPOGRAFICO | C3: hrs | D3: 200 | E3: 43953
A4: 2 | B4: RETROEXCAVADORA | C4: hrs | D4: 150 | E4: 43953
A5: 3 | B5: MEZCLADORA | C5: hrs | D5: 20 | E5: 43953
A6: 4 | B6: VIBRADORA | C6: hrs | D6: 18 | E6: 43953
A7: 5

Sheet CRONOGRAMA
A2: COD | B2: ITEM | C2: FECHA INICIO | D2: DURACION DIAS | E2: FECHA FINAL | F2: FERIADOS
A3: OP 01 | B3: INSTALACION DE FAENAS | C3: 44007 | D3: 1 | E3: =WORKDAY(C3-1,D3,$F$3:$F$14) -> 44007 | F3: 43831 | G3: Año Nuevo
A4: OP 02 | B4: REPLANTEO | C4: =E3 -> 44007 | D4: 3 | E4: =WORKDAY(C4-1,D4,$F$3:$F$14) -> 44011 | F4: 43852 | G4: Dia del estado Plurinacional
A5: OG 01 | B5: EXCAVACION EN SUELO SEMIDURO H=1.5M | C5: =E4 -> 44011 | D5: 12 | E5: =WORKDAY(C5-1,D5,$F$3:$F$14) -> 44026 | F5: 43885 | G5: Carnaval
A6: OG 02 | B6: ZAPATA H° A° | C6: =E5 -> 44026 | D6: 15 | E6: =WORKDAY(C6-1,D6,$F$3:$F$14) -> 44046 | F6: 43886 | G6: Carnaval
A7: OG 03 | B7: CIMIENTO DE HORMIGON CICLOPEO (50%PD) | C7: =E6 -> 44046 | D7: 6 | E7: =WORKDAY(C7-1,D7,$F$3:$F$14) -> 44054 | F7: 43931 | G7: Viernes Santo
A8: OG 04 | B8: SOBRECIMIENTO DE HORMIGON CICLOPEO (50%PD) | C8: =E7 -> 44054 | D8: 4 | E8: =WORKDAY(C8-1,D8,$F$3:$F$14) -> 44057 | F8: 43952 | G8: Dia del trabajado
A9: OG 05 | B9: COLUMNA H° A° | C9: =E8 -> 44057 | D9: 4 | E9: =WORKDAY(C9-1,D9,$F$3:$F$14) -> 44062 | F9: 43993 | G9: Corpus christi
A10: OG 06 | B10: IMPERMEABILIZACION SOBRECIMIENTO C/CARTON ASFALTICO | C10: =E9 -> 44062 | D10: 1 | E10: =WORKDAY(C10-1,D10,$F$3:$F$14) -> 44062 | F10: 44003 | G10: Año Nuevo Aymara
A11: OG 07 | B11: MURO DE 6 HUECOS DE 20cm | C11: =E10 -> 44062 | D11: 20 | E11: =WORKDAY(C11-1,D11,$F$3:$F$14) -> 44089 | F11: 44049 | G11: Dia de la Independencia de Bolivia
A12: OG 08 | B12: MURO DE 6 HUECOS DE 15 cm | C12: 44079 | D12: 15 | E12: =WORKDAY(C12-1,D12,$F$3:$F$14) -> 44099 | F12: 44137 | G12: Dia de todos los Santos
A13: OG 09 | B13: MURO de 6 HUECOS DE 10 cm | C13: 44089 | D13: 6 | E13: =WORKDAY(C13-1,D13,$F$3:$F$14) -> 44096 | F13: 44145 | G13: Dia del departamento de Potosi
A14: OG 10 | B14: VIGA H° A° | C14: =E13 -> 44096 | D14: 13 | E14: =WORKDAY(C14-1,D14,$F$3:$F$14) -> 44112 | F14: 44190 | G14: Navidad
A15: OG 11 | B15: LOSA ALIVIANADA H°A° | C15: =E14 -> 44112 | D15: 10 | E15: =WORKDAY(C15-1,D15,$F$3:$F$14) -> 44125
A16: OG 12 | B16: ESCALERA H° A° | C16: =E15 -> 44125 | D16: 1 | E16: =WORKDAY(C16-1,D16,$F$3:$F$14) -> 44125
A17: OG 13 | B17: CUBIERTA DE CALAMINA ONDULADA | C17: =E16 -> 44125 | D17: 15 | E17: =WORKDAY(C17-1,D17,$F$3:$F$14) -> 44147
A18: OG 14 | B18: DINTEL H° A° | C18: =E17 -> 44147 | D18: 1 | E18: =WORKDAY(C18-1,D18,$F$3:$F$14) -> 44147 | F18: Fecha inicio | G18: =C3 -> 44007
A19: OF 01 | B19: BOTAGUAS DE H° A° | C19: =E18 -> 44147 | D19: 6 | E19: =WORKDAY(C19-1,D19,$F$3:$F$14) -> 44154 | F19: fecha final | G19: =E54 -> 44434
A20: OF 02 | B20: EMPEDRADO Y CONTRAPISO DE H° | C20: =E19 -> 44154 | D20: 10 | E20: =WORKDAY(C20-1,D20,$F$3:$F$14) -> 44167
A21: OF 03 | B21: CONTRAPISO DE CEMENTO S/LOSA | C21: =E20 -> 44167 | D21: 8 | E21: =WORKDAY(C21-1,D21,$F$3:$F$14) -> 44176
A22: OF 04 | B22: PISO DE CERAMICA NACIONAL | C22: =E21 -> 44176 | D22: 8 | E22: =WORKDAY(C22-1,D22,$F$3:$F$14) -> 44187
A23: OF 05 | B23: PISO FLOTANTE | C23: =E22 -> 44187 | D23: 18 | E23: =WORKDAY(C23-1,D23,$F$3:$F$14) -> 44211
A24: OF 06 | B24: REVESTIMIENTO CERAMICA | C24: =E23 -> 44211 | D24: 13 | E24: =WORKDAY(C24-1,D24,$F$3:$F$14) -> 44229
A25: OF 07 | B25: REVOQUE CIELO RASO | C25: =E24 -> 44229 | D25: 12 | E25: =WORKDAY(C25-1,D25,$F$3:$F$14) -> 44244
A26: OF 08 | B26: REVOQUE CIELO RASO S/LOSA | C26: =E25 -> 44244 | D26: 15 | E26: =WORKDAY(C26-1,D26,$F$3:$F$14) -> 44264
A27: OF 09 | B27: REVOQUE EXTERIOR DE CEMENTO | C27: =E26 -> 44264 | D27: 26 | E27: =WORKDAY(C27-1,D27,$F$3:$F$14) -> 44299
A28: OF 10 | B28: REVOQUE INTERIOR DE YESO | C28: =E27 -> 44299 | D28: 31 | E28: =WORKDAY(C28-1,D28,$F$3:$F$14) -> 44341
A29: OF 11 | B29: PUERTA INTERIOR DE MADERA | C29: =E28 -> 44341 | D29: 2 | E29: =WORKDAY(C29-1,D29,$F$3:$F$14) -> 44342
A30: OF 12 | B30: PUERTA EXTERIOR DE MADERA | C30: =E29 -> 44342 | D30: 1 | E30: =WORKDAY(C30-1,D30,$F$3:$F$14) -> 44342
A31: OF 13 | B31: VENTANA DE ALUMINIO | C31: =E30 -> 44342 | D31: 4 | E31: =WORKDAY(C31-1,D31,$F$3:$F$14) -> 44347
... A54: TA 10 | B54: PINTURA ANTICORROSIVA P/CUBIERTA | C54: =E53 -> 44425 | D54: 8 | E54: =WORKDAY(C54-1,D54,$F$3:$F$14) -> 44434
