Workbook
Name Bordillo_jard: COMPUTO!#REF!
Name C_\2015\6_ELECT\16.docx: [1]BD!#REF!
Name Excav_cimien_man: COMPUTO!#REF!
Name LISTA: '[2]POA2008 REF I'!$B$1:$W$3962
Name LISTA: '[2]POA2008 REF I'!$B$1:$W$3962
Name LISTA: '[2]POA2008 REF I'!$B$1:$W$3962
Name LISTA: '[2]POA2008 REF I'!$B$1:$W$3962
Name LISTA: '[2]POA2008 REF I'!$B$1:$W$3962
Name LISTA: '[2]POA2008 REF I'!$B$1:$W$3962
Name LISTA: '[2]POA2008 REF I'!$B$1:$W$3962
Name LISTA: '[3]POA2008 REF I'!$B$1:$W$3962
Name Pis_cem_frot_CP_H4cm: COMPUTO!#REF!

Sheet DATOS
A1: Nro BD | B1: SISIN | C1: PROYECTO | D1: LOCALIZACION | E1: PROV. | F1: CIUDAD
B2: 1005-4984-0000 | C2: RELEVAMIENTO DE VIVIENDA | D2: ARGENTINA | E2: RIO NEGRO | F2: CHUBUT | G2: 0 | H2: 270000 | I2: 0 | J2: 0 | K2: 0 | L2: OBRAS Y MEDIO AMBIENTE | M2: CONSTRUCCIÓN Y MANTENIMIENTO DE CAMINOS VECINALES | N2: NUEVOS
B4: SECRETARIA MUNICIPAL DE PLANIFICACION E INFRAESTRUCTURA URBANA | C4: Ing. Roger Manuel Bellido Salazar
B5: DIRECCION DE PROYECTOS MUNICIPALES
B6: UNIDAD DE PROYECTOS MUNICIPALES
B7: RESPONSABLE DE UNIDAD
B8: RESPONSABLE (S) DE PROYECTO | C8: Ing. Jhony Castillo Villegas
B13: Area del Proyecto: | C13: AREA ARQUITECTURA
B14: Gestion:
B16: DATOS DEL PROYECTO:
B17: Nº BD | C17: 0
B18: Codigo SISIN: | C18: 0
B19: Nombre del Proyecto: | C19: =+C2 -> RELEVAMIENTO DE VIVIENDA
B20: Localizacion: | C20: =+D2 -> ARGENTINA
B21: Prov.: | C21: =+E2 -> RIO NEGRO
B22: Ciudad: | C22: =+F2 -> CHUBUT | D22: Bs
B24: DATOS TECNICOS DEL PROYECTO:
B25: DIMENSIONAMIENTO
B26: Unidad: | C26: M2
B27: Cantidad: | C27: 254
B28: Precio Referencial: | C28: =+#REF! -> #REF! | D28: Bs
B29: Tiempo de ejecucion: | C29: =CRONOG!U3 -> 65 | D29: Dias Calendario
B31: Descripicion tecnica del proyecto:
B32: PARA DESARROLLAR
B33: Alcance del Proyecto
B34: PARA DESARROLLAR
B35: COMPROMISOS DE LA JUNTA VECINAL (SI CORRESPONDE)
B36: la junta de vecinos se hara cargo del recojo de escombros
B38: BENEFICIARIO FINAL para el acta de conformidad | C38: comite de vigalancia
B41: DATOS AUXILIARES
B43: UNIDAD | C43: AREAS DEL PROYECTO | D43: PROYECTISTA
B44: Ml | C44: AREA ARQUITECTURA | D44: Arq. Guadalupe Chavez Choque
B45: M2 | C45: AREA ESTRUCTURAL | D45: Arq. Elsy Carvallo Alfaro
B46: M3 | C46: AREA SANITARIA | D46: Arq. Mariela Zaconeta Abdala
B47: Glb | C47: AREA ELECTRICA | D47: Ing. Javier Quispe Humerez
B48: Pza | C48: AREA HIDRAULICA | D48: Maritza Quispe Mamani
C49: AREA VIAL | D49: Wilmer Rivero Flores
D50: Bacilio Chanez Aima
D51: Ing. Nancy Lopez Apaza
D52: Ing. Franklin Salcedo
...

Sheet CARAT
CE17: PERSONAL CLAVE Y EQUIPO MINIMO
C18: RESUMEN DEL PROYECTO | K18: INGENIERIA DEL PROYECTO | S18: ESTUDIOS BASICOS DE INGENIERIA | AA18: MEMORIAS DE CALCULO | AI18: COMPUTOS METRICOS | AQ18: ANALISIS DE PRECIOS UNITARIOS | AY18: PRESUPUESTO DE CONSTRUCCION | BG18: CRONOGRAMA DE EJECUCION | BO18: PLANOS | BW18: ESPECIFICACIONES TECNICAS | CM18: OTROS DOCUMENTOS | CU18: ACTA DE CONFORMIDAD
AY20: (PLANILLA OFICIAL DE VOLUMENES DE OBRA)
L22: ESTUDIOS BASICOS DE INGENIERIA
C23: ="PROYECTO:"&" "&DATOS!$C$2 -> PROYECTO: RELEVAMIENTO DE VIVIENDA | L23: DISEÑO DE COMPONENTES DE INGENIERIA A DETALLE: | S23: ="PROYECTO:"&" "&DATOS!$C$2 -> PROYECTO: RELEVAMIENTO DE VIVIENDA | AA23: ="PROYECTO:"&" "&DATOS!$C$2 -> PROYECTO: RELEVAMIENTO DE VIVIENDA | AI23: ="PROYECTO:"&" "&DATOS!$C$2 -> PROYECTO: RELEVAMIENTO DE VIVIENDA | AQ23: ="PROYECTO:"&" "&DATOS!$C$2 -> PROYECTO: RELEVAMIENTO DE VIVIENDA | AY23: ="PROYECTO:"&" "&DATOS!$C$2 -> PROYECTO: RELEVAMIENTO DE VIVIENDA | BG23: ="PROYECTO:"&" "&DATOS!$C$2 -> PROYECTO: RELEVAMIENTO DE VIVIENDA | BO23: ="PROYECTO:"&" "&DATOS!$C$2 -> PROYECTO: RELEVAMIENTO DE VIVIENDA | BW23: ="PROYECTO:"&" "&DATOS!$C$2 -> PROYECTO: RELEVAMIENTO DE VIVIENDA | CE23: ="PROYECTO:"&" "&DATOS!$C$2 -> PROYECTO: RELEVAMIENTO DE VIVIENDA | CM23: ="PROYECTO:"&" "&DATOS!$C$2 -> PROYECTO: RELEVAMIENTO DE VIVIENDA | CU23: ="PROYECTO:"&" "&DATOS!$C$2 -> PROYECTO: RELEVAMIENTO DE VIVIENDA
M24: MEMORIAS DE CALCULO
M25: COMPUTOS METRICOS
M26: ANALISIS DE PRECIOS UNITARIOS
G27: ="LOCALIZACION:"&" "&DATOS!$D$2 -> LOCALIZACION: ARGENTINA | M27: PRESUPUESTO DE CONSTRUCCION | W27: ="LOCALIZACION:"&" "&DATOS!$D$2 -> LOCALIZACION: ARGENTINA | AE27: ="LOCALIZACION:"&" "&DATOS!$D$2 -> LOCALIZACION: ARGENTINA | AM27: ="LOCALIZACION:"&" "&DATOS!$D$2 -> LOCALIZACION: ARGENTINA | AU27: ="LOCALIZACION:"&" "&DATOS!$D$2 -> LOCALIZACION: ARGENTINA | BC27: ="LOCALIZACION:"&" "&DATOS!$D$2 -> LOCALIZACION: ARGENTINA | BK27: ="LOCALIZACION:"&" "&DATOS!$D$2 -> LOCALIZACION: ARGENTINA | BS27: ="LOCALIZACION:"&" "&DATOS!$D$2 -> LOCALIZACION: ARGENTINA | CA27: ="LOCALIZACION:"&" "&DATOS!$D$2 -> LOCALIZACION: ARGENTINA | CI27: ="LOCALIZACION:"&" "&DATOS!$D$2 -> LOCALIZACION: ARGENTINA | CQ27: ="LOCALIZACION:"&" "&DATOS!$D$2 -> LOCALIZACION: ARGENTINA | CY27: ="LOCALIZACION:"&" "&DATOS!$D$2 -> LOCALIZACION: ARGENTINA
G28: ="DISTRITO:"&" "&DATOS!$E$2 -> DISTRITO: RIO NEGRO | L28: CRONOGRAMA DE EJECUCION | W28: ="DISTRITO:"&" "&DATOS!$E$2 -> DISTRITO: RIO NEGRO | AE28: ="DISTRITO:"&" "&DATOS!$E$2 -> DISTRITO: RIO NEGRO | AM28: ="DISTRITO:"&" "&DATOS!$E$2 -> DISTRITO: RIO NEGRO | AU28: ="DISTRITO:"&" "&DATOS!$E$2 -> DISTRITO: RIO NEGRO | BC28: ="DISTRITO:"&" "&DATOS!$E$2 -> DISTRITO: RIO NEGRO | BK28: ="DISTRITO:"&" "&DATOS!$E$2 -> DISTRITO: RIO NEGRO | BS28: ="DISTRITO:"&" "&DATOS!$E$2 -> DISTRITO: RIO NEGRO | CA28: ="DISTRITO:"&" "&DATOS!$E$2 -> DISTRITO: RIO NEGRO | CI28: ="DISTRITO:"&" "&DATOS!$E$2 -> DISTRITO: RIO NEGRO | CQ28: ="DISTRITO:"&" "&DATOS!$E$2 -> DISTRITO: RIO NEGRO | CY28: ="DISTRITO:"&" "&DATOS!$E$2 -> DISTRITO: RIO NEGRO
L29: PLANOS
L30: ESPECIFICACIONES TECNICAS
L31: OTROS DOCUMENTOS
L32: ACTA DE CONFORMIDAD
K42: ="PROYECTO:"&" "&DATOS!$C$2 -> PROYECTO: RELEVAMIENTO DE VIVIENDA
O46: ="LOCALIZACION:"&" "&DATOS!$D$2 -> LOCALIZACION: ARGENTINA
O47: ="DISTRITO:"&" "&DATOS!$E$2 -> DISTRITO: RIO NEGRO
D49: GESTION | L49: GESTION | T49: GESTION | AB49: GESTION | AJ49: GESTION | AR49: GESTION | AZ49: GESTION | BH49: GESTION | BP49: GESTION | BX49: GESTION | CF49: GESTION | CN49: GESTION | CV49: GESTION
D50: 2 | E50: 0 | F50: 1 | G50: 6 | L50: 2 | M50: 0 | N50: 1 | O50: 6 | T50: 2 | U50: 0 | V50: 1 | W50: 6 | AB50: 2 | AC50: 0 | AD50: 1 | AE50: 6 | AJ50: 2 | AK50: 0 | AL50: 1 | AM50: 6 | AR50: 2 | AS50: 0 | AT50: 1 | AU50: 6 | AZ50: 2 | BA50: 0 | BB50: 1 | BC50: 6 | BH50: 2 | BI50: 0 | BJ50: 1 | BK50: 6 | BP50: 2 | BQ50: 0 | BR50: 1 | BS50: 6 | BX50: 2 | BY50: 0 | BZ50: 1 | CA50: 6 | CF50: 2 | CG50: 0 | CH50: 1 | CI50: 6 | CN50: 2 | CO50: 0 | CP50: 1 | CQ50: 6 | CV50: 2 | CW50: 0 | CX50: 1 | CY50: 6

Sheet RESUMEN
A2: RESUMEN DEL PROYECTO
A4: DIRECCION DE PROYECTOS MUNICIPALES
A10: 1. DATOS GENERALES DEL PROYECTO.
B12: CODIGO SISIN | C12: NOMBRE DEL PROYECTO | E12: LOCALIZACION | F12: DISTRITO
B14: =+DATOS!C18 -> 0 | C14: =+DATOS!C19 -> RELEVAMIENTO DE VIVIENDA | E14: =+DATOS!C20 -> ARGENTINA | F14: =+DATOS!C21 -> RIO NEGRO
B16: PRECIO REFERENCIAL | C16: MONTO POA | D16: TIEMPO DE EJECUCION | E16: DIMENSIONES DEL PROYECTO
B17: (Bs) | C17: (Bs) | D17: DIAS CALENDARIO | E17: UNIDAD | F17: CANTIDAD
B18: =+DATOS!C28 -> #REF! | C18: =+DATOS!C22 -> CHUBUT | D18: =+DATOS!C29 -> 65 | E18: =+DATOS!C26 -> M2 | F18: =+DATOS!C27 -> 254
B20: UBICACIÓN GEOGRAFICA
B21: DEPARTAMENTO | C21: PROVINCIA | D21: CIUDAD | F21: DISTRITO
B22: LA PAZ | C22: MURILLO | D22: EL ALTO | F22: =+F14 -> RIO NEGRO
B24: INSTITUCION SOLICITANTE
B26: GOBIERNO AUTONOMO MUNICIPAL DE EL ALTO
A28: 2. DESCRIPCION TECNICA DEL PROYECTO.
B30: =CONCATENATE("EL Proyecto ",C14," se emplazara en la zona ",E14," del ",F14,". ",B44,"La dimension del proyecto es de ",F18," ",E18) -> EL Proyecto RELEVAMIENTO DE VIVIENDA se emplazara en la zona ARGENTINA del RIO NEGRO. El proyecto consiste en la construccion de un espacio destinado a centro cultural, en su primera fase esta contemplada la construccion en estructura de la planta baja , ademas de la planta semisotano , debido a la topografia del terreno se esta planteando un muro de contencion, a demas de la construccion de muro de ladrillo en un sector de planbta baja.La dimension del proyecto es de 254 M2
A32: 3. ALCANCE DEL PROYECTO.
B34: =+DATOS!B34 -> PARA DESARROLLAR
B35: =IF(B45=0," ",B45) -> la junta de vecinos se hara cargo del recojo de escombros
A37: 4, TIPO DE INTERVENCION.
B39: DELEGADA
B44: =+[1]DATOS!B32 -> El proyecto consiste en la construccion de un espacio destinado a centro cultural, en su primera fase esta contemplada la construccion en estructura de la planta baja , ademas de la planta semisotano , debido a la topografia del terreno se esta planteando un muro de contencion, a demas de la construccion de muro de ladrillo en un sector de planbta baja.
B45: =+[1]DATOS!B36 -> la junta de vecinos se hara cargo del recojo de escombros

Sheet FICHA TECNICA
A13: ="NOMBRE DEL PROYECTO: "&DATOS!C2 -> NOMBRE DEL PROYECTO: RELEVAMIENTO DE VIVIENDA
A15: DATOS TECNICOS - ECONOMICOS | L15: PLANO DE UBICACIÓN
A17: CODIGO SISIN: | E17: =DATOS!B2 -> 1005-4984-0000
A18: DISTRITO MUNICIPAL: | E18: =DATOS!E2 -> RIO NEGRO
A19: LOCALIZACION: | E19: =DATOS!D2 -> ARGENTINA
A20: UNIDAD DE MEDIDA DEL PROY.: | E20: =DATOS!C26 -> M2
D21: CANTIDAD: | E21: =DATOS!C27 -> 254
A22: PLAZO DE EJECUCION D/C : | E22: =DATOS!C29 -> 65
D23: MONTO POA EN Bs: | E23: =DATOS!C22 -> CHUBUT
D24: MONTO REFERENCIAL EN Bs | E24: =DATOS!C28 -> #REF!
A25: PROYECTISTA RESPONSABLE: | E25: =DATOS!C8 -> Ing. Jhony Castillo Villegas
A27: CONCLUSIONES Y RECOMENDACIONES
A48: DESCRIPCION DEL PROYECTO
A62: INFOGRAFIA DEL PROYECTO

Sheet ITEMS
A1: LISTA DE ITEMS A UTILIZAR EN EL PROYECTO
A2: ITEM | B2: DESCRIPCION | C2: UNIDAD | D2: PRECIO UNITARIO | E2: N° | H2: FASES DEL PROYECTO | P2: FASES DEL PROYECTO
A3: 512 | B3: =IF(A3=0," ",LOOKUP(A3,BD!$B$7:$B$2996,BD!$C$7:$C$2996)) -> EXCAVACIÓN C/MAQ (INCLUYE CARG. Y TRANSP. ÁREA DE LA OBRA) | C3: =IF(A3=0," ",LOOKUP(A3,BD!$B$7:$B$2996,BD!$D$7:$D$2996)) -> M3 | D3: =IF(A3=0," ",LOOKUP(A3,BD!$B$7:$B$2996,BD!$E$7:$E$2996)) -> 28.6 | E3: =IF(A3=0," ",1) -> 1 | G3: =IF(H3=0," ","A") -> A | H3: OBRAS PRELIMINARES | O3: A | P3: ALCANTARILLADO PLUVIAL
A4: 1393 | B4: =IF(A4=0," ",LOOKUP(A4,BD!$B$7:$B$2996,BD!$C$7:$C$2996)) -> DESENLOSETADO | C4: =IF(A4=0," ",LOOKUP(A4,BD!$B$7:$B$2996,BD!$D$7:$D$2996)) -> M2 | D4: =IF(A4=0," ",LOOKUP(A4,BD!$B$7:$B$2996,BD!$E$7:$E$2996)) -> 6.44 | E4: =IF(A4=0," ",(E3+1)) -> 2 | G4: =IF(H4=0," ","B") | O4: B | P4: INFRAESTRUCTURA
A5: 450 | B5: =IF(A5=0," ",LOOKUP(A5,BD!$B$7:$B$2996,BD!$C$7:$C$2996)) -> VENTANA DE MADERA ROBLE 2" | C5: =IF(A5=0," ",LOOKUP(A5,BD!$B$7:$B$2996,BD!$D$7:$D$2996)) -> M2 | D5: =IF(A5=0," ",LOOKUP(A5,BD!$B$7:$B$2996,BD!$E$7:$E$2996)) -> 466.07 | E5: =IF(A5=0," ",(E4+1)) -> 3
A6: 2 | B6: =IF(A6=0," ",LOOKUP(A6,BD!$B$7:$B$2996,BD!$C$7:$C$2996)) -> ACERA DE CEMENTO E=10 CM SIN EMPEDRADO | C6: =IF(A6=0," ",LOOKUP(A6,BD!$B$7:$B$2996,BD!$D$7:$D$2996)) -> M2 | D6: =IF(A6=0," ",LOOKUP(A6,BD!$B$7:$B$2996,BD!$E$7:$E$2996)) -> 155.42 | E6: =IF(A6=0," ",(E5+1)) -> 4
A7: 1586 | B7: =IF(A7=0," ",LOOKUP(A7,BD!$B$7:$B$2996,BD!$C$7:$C$2996)) -> VALVULA DE GAS D=2" PARA AN (PROV. E INST.) | C7: =IF(A7=0," ",LOOKUP(A7,BD!$B$7:$B$2996,BD!$D$7:$D$2996)) -> PZA | D7: =IF(A7=0," ",LOOKUP(A7,BD!$B$7:$B$2996,BD!$E$7:$E$2996)) -> 425.01 | E7: =IF(A7=0," ",(E6+1)) -> 5 | G7: =IF(H7=0," ","C") | O7: C | P7: INSTALACION AGUA POTABLE
A8: 1247 | B8: =IF(A8=0," ",LOOKUP(A8,BD!$B$7:$B$2996,BD!$C$7:$C$2996)) -> Y PVC CLASE 9 D=4" (PROV. Y COLOC.) | C8: =IF(A8=0," ",LOOKUP(A8,BD!$B$7:$B$2996,BD!$D$7:$D$2996)) -> PZA | D8: =IF(A8=0," ",LOOKUP(A8,BD!$B$7:$B$2996,BD!$E$7:$E$2996)) -> 49.45 | E8: =IF(A8=0," ",(E7+1)) -> 6 | G8: =IF(H8=0," ","D") | O8: D | P8: INSTALACION ELECTRICA
A9: 254 | B9: =IF(A9=0," ",LOOKUP(A9,BD!$B$7:$B$2996,BD!$C$7:$C$2996)) -> PINTURA EN INTERIORES LATEX O SIMILARES (DOS MANOS) | C9: =IF(A9=0," ",LOOKUP(A9,BD!$B$7:$B$2996,BD!$D$7:$D$2996)) -> M2 | D9: =IF(A9=0," ",LOOKUP(A9,BD!$B$7:$B$2996,BD!$E$7:$E$2996)) -> 52.27 | E9: =IF(A9=0," ",(E8+1)) -> 7
A10: 235 | B10: =IF(A10=0," ",LOOKUP(A10,BD!$B$7:$B$2996,BD!$C$7:$C$2996)) -> PICADO REVOQUE DE CEMENTO | C10: =IF(A10=0," ",LOOKUP(A10,BD!$B$7:$B$2996,BD!$D$7:$D$2996)) -> M2 | D10: =IF(A10=0," ",LOOKUP(A10,BD!$B$7:$B$2996,BD!$E$7:$E$2996)) -> 18.04 | E10: =IF(A10=0," ",(E9+1)) -> 8 | G10: =IF(H10=0," ","E") | O10: E | P10: INSTALACION PLUVIAL
A11: 698 | B11: =IF(A11=0," ",LOOKUP(A11,BD!$B$7:$B$2996,BD!$C$7:$C$2996)) -> CABLE COBRE AISLADO 7 H Nº 8 AWG TW (PROV. E INST.) | C11: =IF(A11=0," ",LOOKUP(A11,BD!$B$7:$B$2996,BD!$D$7:$D$2996)) -> ML | D11: =IF(A11=0," ",LOOKUP(A11,BD!$B$7:$B$2996,BD!$E$7:$E$2996)) -> 32.76 | E11: =IF(A11=0," ",(E10+1)) -> 9 | G11: =IF(H11=0," ","F") | O11: F | P11: INSTALACION SANITARIA
A12: 3255 | B12: =IF(A12=0," ",LOOKUP(A12,BD!$B$7:$B$2996,BD!$C$7:$C$2996)) -> VENTILADOR DE 300 M3/H | C12: =IF(A12=0," ",LOOKUP(A12,BD!$B$7:$B$2996,BD!$D$7:$D$2996)) -> PZA | D12: =IF(A12=0," ",LOOKUP(A12,BD!$B$7:$B$2996,BD!$E$7:$E$2996)) -> 1280.63 | E12: =IF(A12=0," ",(E11+1)) -> 10 | G12: =IF(H12=0," ","G") | O12: G | P12: MOVILIZACION
A13: 154 | B13: =IF(A13=0," ",LOOKUP(A13,BD!$B$7:$B$2996,BD!$C$7:$C$2996)) -> INSTALACION CESPED SINTETICO H=50 MM | C13: =IF(A13=0," ",LOOKUP(A13,BD!$B$7:$B$2996,BD!$D$7:$D$2996)) -> M2 | D13: =IF(A13=0," ",LOOKUP(A13,BD!$B$7:$B$2996,BD!$E$7:$E$2996)) -> 61.11 | E13: =IF(A13=0," ",(E12+1)) -> 11 | G13: =IF(H13=0," ","H") | O13: H | P13: MOVIMIENTO DE TIERRAS
A14: 55 | B14: =IF(A14=0," ",LOOKUP(A14,BD!$B$7:$B$2996,BD!$C$7:$C$2996)) -> CANALETA DE CALAMINA PLANA N°28 CORTE 60 EN LIMAHOYA | C14: =IF(A14=0," ",LOOKUP(A14,BD!$B$7:$B$2996,BD!$D$7:$D$2996)) -> ML | D14: =IF(A14=0," ",LOOKUP(A14,BD!$B$7:$B$2996,BD!$E$7:$E$2996)) -> 145.95 | E14: =IF(A14=0," ",(E13+1)) -> 12 | G14: =IF(H14=0," ","I") | O14: I | P14: OBRA FINA
B15: =IF(A15=0," ",LOOKUP(A15,BD!$B$7:$B$2996,BD!$C$7:$C$2996)) | C15: =IF(A15=0," ",LOOKUP(A15,BD!$B$7:$B$2996,BD!$D$7:$D$2996)) | D15: =IF(A15=0," ",LOOKUP(A15,BD!$B$7:$B$2996,BD!$E$7:$E$2996)) | E15: =IF(A15=0," ",(E14+1))
B16: =IF(A16=0," ",LOOKUP(A16,BD!$B$7:$B$2996,BD!$C$7:$C$2996)) | C16: =IF(A16=0," ",LOOKUP(A16,BD!$B$7:$B$2996,BD!$D$7:$D$2996)) | D16: =IF(A16=0," ",LOOKUP(A16,BD!$B$7:$B$2996,BD!$E$7:$E$2996)) | E16: =IF(A16=0," ",(E15+1)) | G16: =IF(H16=0," ","J") | O16: J | P16: OBRA GRUESA
B17: =IF(A17=0," ",LOOKUP(A17,BD!$B$7:$B$2996,BD!$C$7:$C$2996)) | C17: =IF(A17=0," ",LOOKUP(A17,BD!$B$7:$B$2996,BD!$D$7:$D$2996)) | D17: =IF(A17=0," ",LOOKUP(A17,BD!$B$7:$B$2996,BD!$E$7:$E$2996)) | E17: =IF(A17=0," ",(E16+1)) | O17: K | P17: OBRAS COMPLEMENTARIAS
B18: =IF(A18=0," ",LOOKUP(A18,BD!$B$7:$B$2996,BD!$C$7:$C$2996)) | C18: =IF(A18=0," ",LOOKUP(A18,BD!$B$7:$B$2996,BD!$D$7:$D$2996)) | D18: =IF(A18=0," ",LOOKUP(A18,BD!$B$7:$B$2996,BD!$E$7:$E$2996)) | E18: =IF(A18=0," ",(E17+1)) | O18: L | P18: OBRAS DE DRENAJE
B19: =IF(A19=0," ",LOOKUP(A19,BD!$B$7:$B$2996,BD!$C$7:$C$2996)) | C19: =IF(A19=0," ",LOOKUP(A19,BD!$B$7:$B$2996,BD!$D$7:$D$2996)) | D19: =IF(A19=0," ",LOOKUP(A19,BD!$B$7:$B$2996,BD!$E$7:$E$2996)) | E19: =IF(A19=0," ",(E18+1)) | O19: M | P19: OBRAS DE ENLOSETADO
B20: =IF(A20=0," ",LOOKUP(A20,BD!$B$7:$B$2996,BD!$C$7:$C$2996)) | C20: =IF(A20=0," ",LOOKUP(A20,BD!$B$7:$B$2996,BD!$D$7:$D$2996)) | D20: =IF(A20=0," ",LOOKUP(A20,BD!$B$7:$B$2996,BD!$E$7:$E$2996)) | E20: =IF(A20=0," ",(E19+1)) | O20: N | P20: OBRAS PRELIMINARES
B21: =IF(A21=0," ",LOOKUP(A21,BD!$B$7:$B$2996,BD!$C$7:$C$2996)) | C21: =IF(A21=0," ",LOOKUP(A21,BD!$B$7:$B$2996,BD!$D$7:$D$2996)) | D21: =IF(A21=0," ",LOOKUP(A21,BD!$B$7:$B$2996,BD!$E$7:$E$2996)) | E21: =IF(A21=0," ",(E20+1)) | O21: O | P21: PAVIMENTACION DE CALZADA
B22: =IF(A22=0," ",LOOKUP(A22,BD!$B$7:$B$2996,BD!$C$7:$C$2996)) | C22: =IF(A22=0," ",LOOKUP(A22,BD!$B$7:$B$2996,BD!$D$7:$D$2996)) | D22: =IF(A22=0," ",LOOKUP(A22,BD!$B$7:$B$2996,BD!$E$7:$E$2996)) | E22: =IF(A22=0," ",(E21+1)) | O22: P | P22: SEÑALIZACION
B23: =IF(A23=0," ",LOOKUP(A23,BD!$B$7:$B$2996,BD!$C$7:$C$2996)) | C23: =IF(A23=0," ",LOOKUP(A23,BD!$B$7:$B$2996,BD!$D$7:$D$2996)) | D23: =IF(A23=0," ",LOOKUP(A23,BD!$B$7:$B$2996,BD!$E$7:$E$2996)) | E23: =IF(A23=0," ",(E22+1)) | O23: Q | P23: SUMIDEROS
B24: =IF(A24=0," ",LOOKUP(A24,BD!$B$7:$B$2996,BD!$C$7:$C$2996)) | C24: =IF(A24=0," ",LOOKUP(A24,BD!$B$7:$B$2996,BD!$D$7:$D$2996)) | D24: =IF(A24=0," ",LOOKUP(A24,BD!$B$7:$B$2996,BD!$E$7:$E$2996)) | E24: =IF(A24=0," ",(E23+1)) | O24: R | P24: SUPERESTRUCTURA
B25: =IF(A25=0," ",LOOKUP(A25,BD!$B$7:$B$2996,BD!$C$7:$C$2996)) | C25: =IF(A25=0," ",LOOKUP(A25,BD!$B$7:$B$2996,BD!$D$7:$D$2996)) | D25: =IF(A25=0," ",LOOKUP(A25,BD!$B$7:$B$2996,BD!$E$7:$E$2996)) | E25: =IF(A25=0," ",(E24+1)) | O25: S
B26: =IF(A26=0," ",LOOKUP(A26,BD!$B$7:$B$2996,BD!$C$7:$C$2996)) | C26: =IF(A26=0," ",LOOKUP(A26,BD!$B$7:$B$2996,BD!$D$7:$D$2996)) | D26: =IF(A26=0," ",LOOKUP(A26,BD!$B$7:$B$2996,BD!$E$7:$E$2996)) | E26: =IF(A26=0," ",(E25+1)) | O26: T
B27: =IF(A27=0," ",LOOKUP(A27,BD!$B$7:$B$2996,BD!$C$7:$C$2996)) | C27: =IF(A27=0," ",LOOKUP(A27,BD!$B$7:$B$2996,BD!$D$7:$D$2996)) | D27: =IF(A27=0," ",LOOKUP(A27,BD!$B$7:$B$2996,BD!$E$7:$E$2996)) | E27: =IF(A27=0," ",(E26+1))
B28: =IF(A28=0," ",LOOKUP(A28,BD!$B$7:$B$2996,BD!$C$7:$C$2996)) | C28: =IF(A28=0," ",LOOKUP(A28,BD!$B$7:$B$2996,BD!$D$7:$D$2996)) | D28: =IF(A28=0," ",LOOKUP(A28,BD!$B$7:$B$2996,BD!$E$7:$E$2996)) | E28: =IF(A28=0," ",(E27+1))
B29: =IF(A29=0," ",LOOKUP(A29,BD!$B$7:$B$2996,BD!$C$7:$C$2996)) | C29: =IF(A29=0," ",LOOKUP(A29,BD!$B$7:$B$2996,BD!$D$7:$D$2996)) | D29: =IF(A29=0," ",LOOKUP(A29,BD!$B$7:$B$2996,BD!$E$7:$E$2996)) | E29: =IF(A29=0," ",(E28+1))
B30: =IF(A30=0," ",LOOKUP(A30,BD!$B$7:$B$2996,BD!$C$7:$C$2996)) | C30: =IF(A30=0," ",LOOKUP(A30,BD!$B$7:$B$2996,BD!$D$7:$D$2996)) | D30: =IF(A30=0," ",LOOKUP(A30,BD!$B$7:$B$2996,BD!$E$7:$E$2996)) | E30: =IF(A30=0," ",(E29+1))
B31: =IF(A31=0," ",LOOKUP(A31,BD!$B$7:$B$2996,BD!$C$7:$C$2996)) | C31: =IF(A31=0," ",LOOKUP(A31,BD!$B$7:$B$2996,BD!$D$7:$D$2996)) | D31: =IF(A31=0," ",LOOKUP(A31,BD!$B$7:$B$2996,BD!$E$7:$E$2996)) | E31: =IF(A31=0," ",(E30+1))
B32: =IF(A32=0," ",LOOKUP(A32,BD!$B$7:$B$2996,BD!$C$7:$C$2996)) | C32: =IF(A32=0," ",LOOKUP(A32,BD!$B$7:$B$2996,BD!$D$7:$D$2996)) | D32: =IF(A32=0," ",LOOKUP(A32,BD!$B$7:$B$2996,BD!$E$7:$E$2996)) | E32: =IF(A32=0," ",(E31+1))
B33: =IF(A33=0," ",LOOKUP(A33,BD!$B$7:$B$2996,BD!$C$7:$C$2996)) | C33: =IF(A33=0," ",LOOKUP(A33,BD!$B$7:$B$2996,BD!$D$7:$D$2996)) | D33: =IF(A33=0," ",LOOKUP(A33,BD!$B$7:$B$2996,BD!$E$7:$E$2996)) | E33: =IF(A33=0," ",(E32+1))
B34: =IF(A34=0," ",LOOKUP(A34,BD!$B$7:$B$2996,BD!$C$7:$C$2996)) | C34: =IF(A34=0," ",LOOKUP(A34,BD!$B$7:$B$2996,BD!$D$7:$D$2996)) | D34: =IF(A34=0," ",LOOKUP(A34,BD!$B$7:$B$2996,BD!$E$7:$E$2996)) | E34: =IF(A34=0," ",(E33+1))
B35: =IF(A35=0," ",LOOKUP(A35,BD!$B$7:$B$2996,BD!$C$7:$C$2996)) | C35: =IF(A35=0," ",LOOKUP(A35,BD!$B$7:$B$2996,BD!$D$7:$D$2996)) | D35: =IF(A35=0," ",LOOKUP(A35,BD!$B$7:$B$2996,BD!$E$7:$E$2996)) | E35: =IF(A35=0," ",(E34+1))
B36: =IF(A36=0," ",LOOKUP(A36,BD!$B$7:$B$2996,BD!$C$7:$C$2996)) | C36: =IF(A36=0," ",LOOKUP(A36,BD!$B$7:$B$2996,BD!$D$7:$D$2996)) | D36: =IF(A36=0," ",LOOKUP(A36,BD!$B$7:$B$2996,BD!$E$7:$E$2996)) | E36: =IF(A36=0," ",(E35+1))
B37: =IF(A37=0," ",LOOKUP(A37,BD!$B$7:$B$2996,BD!$C$7:$C$2996)) | C37: =IF(A37=0," ",LOOKUP(A37,BD!$B$7:$B$2996,BD!$D$7:$D$2996)) | D37: =IF(A37=0," ",LOOKUP(A37,BD!$B$7:$B$2996,BD!$E$7:$E$2996)) | E37: =IF(A37=0," ",(E36+1))
B38: =IF(A38=0," ",LOOKUP(A38,BD!$B$7:$B$2996,BD!$C$7:$C$2996)) | C38: =IF(A38=0," ",LOOKUP(A38,BD!$B$7:$B$2996,BD!$D$7:$D$2996)) | D38: =IF(A38=0," ",LOOKUP(A38,BD!$B$7:$B$2996,BD!$E$7:$E$2996)) | E38: =IF(A38=0," ",(E37+1))
... B117: =IF(A117=0," ",LOOKUP(A117,BD!$B$7:$B$2996,BD!$C$7:$C$2996)) | C117: =IF(A117=0," ",LOOKUP(A117,BD!$B$7:$B$2996,BD!$D$7:$D$2996)) | D117: =IF(A117=0," ",LOOKUP(A117,BD!$B$7:$B$2996,BD!$E$7:$E$2996)) | E117: =IF(A117=0," ",(E116+1))
D126: M3 | E126: 6
...

Sheet B1 
A2: PLANILLA OFICIAL DE VOLUMENES DE OBRA
A5: ="PROYECTO: "&DATOS!C2 -> PROYECTO: RELEVAMIENTO DE VIVIENDA
A7: ="LOCALIZACION:"&DATOS!D2 -> LOCALIZACION:ARGENTINA | F7: =""&DATOS!C13 -> AREA ARQUITECTURA
A8: ="DISTRITO:"&DATOS!E2 -> DISTRITO:RIO NEGRO
J9: ESTRUCTURAL | K9: INFRAESTRUCTURA
K10: SUPERESTRUCTURA
C11: UNIDAD DE | D11: CANTIDAD | E11: PRECIO | F11: PRECIO UNITARIO LITERAL | G11: PRECIOS | K11: INSTALACION AGUA POTABLE
A12: No ÍTEM | B12: DESCRIPCIÓN DE LOS ÍTEMS | C12: MEDIDA | D12: CALCULADA | E12: UNITARIO | G12: PARCIALES | J12: SANITARIA | K12: INSTALACION SANITARIA
B13: MOVIMIENTO DE TIERRAS | K13: INSTALACION ELECTRICA
A14: 1 | B14: =IF(A14=0," ",LOOKUP(A14,ITEMS!$E$3:$E$106,ITEMS!$B$3:$B$106)) -> EXCAVACIÓN C/MAQ (INCLUYE CARG. Y TRANSP. ÁREA DE LA OBRA) | C14: =IF(A14=0," ",LOOKUP(A14,ITEMS!$E$3:$E$106,ITEMS!$C$3:$C$106)) -> M3 | D14: =IF(A14=0," ",LOOKUP(A14,COMPUTO!$A$14:$A$922,COMPUTO!$K$14:$K$921)) -> 1 | E14: =IF(A14=0," ",LOOKUP(A14,ITEMS!$E$3:$E$106,ITEMS!$D$3:$D$106)) -> 28.6 | G14: =IF(A14=0,0,ROUND((D14*E14),2)) -> 28.6 | J14: ELECTRICA | K14: INSTALACION ELECTRICA
A15: 2 | B15: =IF(A15=0," ",LOOKUP(A15,ITEMS!$E$3:$E$106,ITEMS!$B$3:$B$106)) -> DESENLOSETADO | C15: =IF(A15=0," ",LOOKUP(A15,ITEMS!$E$3:$E$106,ITEMS!$C$3:$C$106)) -> M2 | D15: =IF(A15=0," ",LOOKUP(A15,COMPUTO!$A$14:$A$922,COMPUTO!$K$14:$K$921)) -> 1 | E15: =IF(A15=0," ",LOOKUP(A15,ITEMS!$E$3:$E$106,ITEMS!$D$3:$D$106)) -> 6.44 | G15: =IF(A15=0,0,ROUND((D15*E15),2)) -> 6.44 | J15: ELECTRICA
A16: 3 | B16: =IF(A16=0," ",LOOKUP(A16,ITEMS!$E$3:$E$106,ITEMS!$B$3:$B$106)) -> VENTANA DE MADERA ROBLE 2" | C16: =IF(A16=0," ",LOOKUP(A16,ITEMS!$E$3:$E$106,ITEMS!$C$3:$C$106)) -> M2 | D16: =IF(A16=0," ",LOOKUP(A16,COMPUTO!$A$14:$A$922,COMPUTO!$K$14:$K$921)) -> 1 | E16: =IF(A16=0," ",LOOKUP(A16,ITEMS!$E$3:$E$106,ITEMS!$D$3:$D$106)) -> 466.07 | G16: =IF(A16=0,0,ROUND((D16*E16),2)) -> 466.07
A17: 4 | B17: =IF(A17=0," ",LOOKUP(A17,ITEMS!$E$3:$E$106,ITEMS!$B$3:$B$106)) -> ACERA DE CEMENTO E=10 CM SIN EMPEDRADO | C17: =IF(A17=0," ",LOOKUP(A17,ITEMS!$E$3:$E$106,ITEMS!$C$3:$C$106)) -> M2 | D17: =IF(A17=0," ",LOOKUP(A17,COMPUTO!$A$14:$A$922,COMPUTO!$K$14:$K$921)) -> 1 | E17: =IF(A17=0," ",LOOKUP(A17,ITEMS!$E$3:$E$106,ITEMS!$D$3:$D$106)) -> 155.42 | G17: =IF(A17=0,0,ROUND((D17*E17),2)) -> 155.42
A18: 5 | B18: =IF(A18=0," ",LOOKUP(A18,ITEMS!$E$3:$E$106,ITEMS!$B$3:$B$106)) -> VALVULA DE GAS D=2" PARA AN (PROV. E INST.) | C18: =IF(A18=0," ",LOOKUP(A18,ITEMS!$E$3:$E$106,ITEMS!$C$3:$C$106)) -> PZA | D18: =IF(A18=0," ",LOOKUP(A18,COMPUTO!$A$14:$A$922,COMPUTO!$K$14:$K$921)) -> 1 | E18: =IF(A18=0," ",LOOKUP(A18,ITEMS!$E$3:$E$106,ITEMS!$D$3:$D$106)) -> 425.01 | G18: =IF(A18=0,0,ROUND((D18*E18),2)) -> 425.01
A19: 6 | B19: =IF(A19=0," ",LOOKUP(A19,ITEMS!$E$3:$E$106,ITEMS!$B$3:$B$106)) -> Y PVC CLASE 9 D=4" (PROV. Y COLOC.) | C19: =IF(A19=0," ",LOOKUP(A19,ITEMS!$E$3:$E$106,ITEMS!$C$3:$C$106)) -> PZA | D19: =IF(A19=0," ",LOOKUP(A19,COMPUTO!$A$14:$A$922,COMPUTO!$K$14:$K$921)) -> 1 | E19: =IF(A19=0," ",LOOKUP(A19,ITEMS!$E$3:$E$106,ITEMS!$D$3:$D$106)) -> 49.45 | G19: =IF(A19=0,0,ROUND((D19*E19),2)) -> 49.45
A20: 7 | B20: =IF(A20=0," ",LOOKUP(A20,ITEMS!$E$3:$E$106,ITEMS!$B$3:$B$106)) -> PINTURA EN INTERIORES LATEX O SIMILARES (DOS MANOS) | C20: =IF(A20=0," ",LOOKUP(A20,ITEMS!$E$3:$E$106,ITEMS!$C$3:$C$106)) -> M2 | D20: =IF(A20=0," ",LOOKUP(A20,COMPUTO!$A$14:$A$922,COMPUTO!$K$14:$K$921)) -> 1 | E20: =IF(A20=0," ",LOOKUP(A20,ITEMS!$E$3:$E$106,ITEMS!$D$3:$D$106)) -> 52.27 | G20: =IF(A20=0,0,ROUND((D20*E20),2)) -> 52.27
A21: 8 | B21: =IF(A21=0," ",LOOKUP(A21,ITEMS!$E$3:$E$106,ITEMS!$B$3:$B$106)) -> PICADO REVOQUE DE CEMENTO | C21: =IF(A21=0," ",LOOKUP(A21,ITEMS!$E$3:$E$106,ITEMS!$C$3:$C$106)) -> M2 | D21: =IF(A21=0," ",LOOKUP(A21,COMPUTO!$A$14:$A$922,COMPUTO!$K$14:$K$921)) -> 1 | E21: =IF(A21=0," ",LOOKUP(A21,ITEMS!$E$3:$E$106,ITEMS!$D$3:$D$106)) -> 18.04 | G21: =IF(A21=0,0,ROUND((D21*E21),2)) -> 18.04
A22: 9 | B22: =IF(A22=0," ",LOOKUP(A22,ITEMS!$E$3:$E$106,ITEMS!$B$3:$B$106)) -> CABLE COBRE AISLADO 7 H Nº 8 AWG TW (PROV. E INST.) | C22: =IF(A22=0," ",LOOKUP(A22,ITEMS!$E$3:$E$106,ITEMS!$C$3:$C$106)) -> ML | D22: =IF(A22=0," ",LOOKUP(A22,COMPUTO!$A$14:$A$922,COMPUTO!$K$14:$K$921)) -> 1 | E22: =IF(A22=0," ",LOOKUP(A22,ITEMS!$E$3:$E$106,ITEMS!$D$3:$D$106)) -> 32.76 | G22: =IF(A22=0,0,ROUND((D22*E22),2)) -> 32.76
A23: 10 | B23: =IF(A23=0," ",LOOKUP(A23,ITEMS!$E$3:$E$106,ITEMS!$B$3:$B$106)) -> VENTILADOR DE 300 M3/H | C23: =IF(A23=0," ",LOOKUP(A23,ITEMS!$E$3:$E$106,ITEMS!$C$3:$C$106)) -> PZA | D23: =IF(A23=0," ",LOOKUP(A23,COMPUTO!$A$14:$A$922,COMPUTO!$K$14:$K$921)) -> 1 | E23: =IF(A23=0," ",LOOKUP(A23,ITEMS!$E$3:$E$106,ITEMS!$D$3:$D$106)) -> 1280.63 | G23: =IF(A23=0,0,ROUND((D23*E23),2)) -> 1280.63
A24: 11 | B24: =IF(A24=0," ",LOOKUP(A24,ITEMS!$E$3:$E$106,ITEMS!$B$3:$B$106)) -> INSTALACION CESPED SINTETICO H=50 MM | C24: =IF(A24=0," ",LOOKUP(A24,ITEMS!$E$3:$E$106,ITEMS!$C$3:$C$106)) -> M2 | D24: =IF(A24=0," ",LOOKUP(A24,COMPUTO!$A$14:$A$922,COMPUTO!$K$14:$K$921)) -> 1 | E24: =IF(A24=0," ",LOOKUP(A24,ITEMS!$E$3:$E$106,ITEMS!$D$3:$D$106)) -> 61.11 | G24: =IF(A24=0,0,ROUND((D24*E24),2)) -> 61.11
B25: =IF(A25=0," ",LOOKUP(A25,ITEMS!$E$3:$E$106,ITEMS!$B$3:$B$106)) | C25: =IF(A25=0," ",LOOKUP(A25,ITEMS!$E$3:$E$106,ITEMS!$C$3:$C$106)) | D25: =IF(A25=0," ",LOOKUP(A25,COMPUTO!$A$14:$A$922,COMPUTO!$K$14:$K$921)) | E25: =IF(A25=0," ",LOOKUP(A25,ITEMS!$E$3:$E$106,ITEMS!$D$3:$D$106)) | G25: =IF(A25=0,0,ROUND((D25*E25),2)) -> 0
B26: =IF(A26=0," ",LOOKUP(A26,ITEMS!$E$3:$E$106,ITEMS!$B$3:$B$106)) | C26: =IF(A26=0," ",LOOKUP(A26,ITEMS!$E$3:$E$106,ITEMS!$C$3:$C$106)) | D26: =IF(A26=0," ",LOOKUP(A26,COMPUTO!$A$14:$A$922,COMPUTO!$K$14:$K$921)) | E26: =IF(A26=0," ",LOOKUP(A26,ITEMS!$E$3:$E$106,ITEMS!$D$3:$D$106)) | G26: =IF(A26=0,0,ROUND((D26*E26),2)) -> 0
B27: =IF(A27=0," ",LOOKUP(A27,ITEMS!$E$3:$E$106,ITEMS!$B$3:$B$106)) | C27: =IF(A27=0," ",LOOKUP(A27,ITEMS!$E$3:$E$106,ITEMS!$C$3:$C$106)) | D27: =IF(A27=0," ",LOOKUP(A27,COMPUTO!$A$14:$A$922,COMPUTO!$K$14:$K$921)) | E27: =IF(A27=0," ",LOOKUP(A27,ITEMS!$E$3:$E$106,ITEMS!$D$3:$D$106)) | G27: =IF(A27=0,0,ROUND((D27*E27),2)) -> 0
B28: =IF(A28=0," ",LOOKUP(A28,ITEMS!$E$3:$E$106,ITEMS!$B$3:$B$106)) | C28: =IF(A28=0," ",LOOKUP(A28,ITEMS!$E$3:$E$106,ITEMS!$C$3:$C$106)) | D28: =IF(A28=0," ",LOOKUP(A28,COMPUTO!$A$14:$A$922,COMPUTO!$K$14:$K$921)) | E28: =IF(A28=0," ",LOOKUP(A28,ITEMS!$E$3:$E$106,ITEMS!$D$3:$D$106)) | G28: =IF(A28=0,0,ROUND((D28*E28),2)) -> 0
B29: =IF(A29=0," ",LOOKUP(A29,ITEMS!$E$3:$E$106,ITEMS!$B$3:$B$106)) | C29: =IF(A29=0," ",LOOKUP(A29,ITEMS!$E$3:$E$106,ITEMS!$C$3:$C$106)) | D29: =IF(A29=0," ",LOOKUP(A29,COMPUTO!$A$14:$A$922,COMPUTO!$K$14:$K$921)) | E29: =IF(A29=0," ",LOOKUP(A29,ITEMS!$E$3:$E$106,ITEMS!$D$3:$D$106)) | G29: =IF(A29=0,0,ROUND((D29*E29),2)) -> 0
B30: =IF(A30=0," ",LOOKUP(A30,[1]ITEMS!$E$3:$E$106,[1]ITEMS!$B$3:$B$106)) | C30: =IF(A30=0," ",LOOKUP(A30,[1]ITEMS!$E$3:$E$106,[1]ITEMS!$C$3:$C$106)) | D30: =IF(A30=0," ",LOOKUP(A30,[1]COMPUTO!$A$14:$A$922,[1]COMPUTO!$K$14:$K$921)) | E30: =IF(A30=0," ",LOOKUP(A30,[1]ITEMS!$E$3:$E$106,[1]ITEMS!$D$3:$D$106)) | G30: =IF(A30=0,0,ROUND((D30*E30),2)) -> 0
B31: =IF(A31=0," ",LOOKUP(A31,[1]ITEMS!$E$3:$E$106,[1]ITEMS!$B$3:$B$106)) | C31: =IF(A31=0," ",LOOKUP(A31,[1]ITEMS!$E$3:$E$106,[1]ITEMS!$C$3:$C$106)) | D31: =IF(A31=0," ",LOOKUP(A31,[1]COMPUTO!$A$14:$A$922,[1]COMPUTO!$K$14:$K$921)) | E31: =IF(A31=0," ",LOOKUP(A31,[1]ITEMS!$E$3:$E$106,[1]ITEMS!$D$3:$D$106)) | G31: =IF(A31=0,0,ROUND((D31*E31),2)) -> 0
B32: =IF(A32=0," ",LOOKUP(A32,[1]ITEMS!$E$3:$E$106,[1]ITEMS!$B$3:$B$106)) | C32: =IF(A32=0," ",LOOKUP(A32,[1]ITEMS!$E$3:$E$106,[1]ITEMS!$C$3:$C$106)) | D32: =IF(A32=0," ",LOOKUP(A32,[1]COMPUTO!$A$14:$A$922,[1]COMPUTO!$K$14:$K$921)) | E32: =IF(A32=0," ",LOOKUP(A32,[1]ITEMS!$E$3:$E$106,[1]ITEMS!$D$3:$D$106)) | G32: =IF(A32=0,0,ROUND((D32*E32),2)) -> 0
B33: =IF(A33=0," ",LOOKUP(A33,[1]ITEMS!$E$3:$E$106,[1]ITEMS!$B$3:$B$106)) | C33: =IF(A33=0," ",LOOKUP(A33,[1]ITEMS!$E$3:$E$106,[1]ITEMS!$C$3:$C$106)) | D33: =IF(A33=0," ",LOOKUP(A33,[1]COMPUTO!$A$14:$A$922,[1]COMPUTO!$K$14:$K$921)) | E33: =IF(A33=0," ",LOOKUP(A33,[1]ITEMS!$E$3:$E$106,[1]ITEMS!$D$3:$D$106)) | G33: =IF(A33=0,0,ROUND((D33*E33),2)) -> 0
B34: =IF(A34=0," ",LOOKUP(A34,[1]ITEMS!$E$3:$E$106,[1]ITEMS!$B$3:$B$106)) | C34: =IF(A34=0," ",LOOKUP(A34,[1]ITEMS!$E$3:$E$106,[1]ITEMS!$C$3:$C$106)) | D34: =IF(A34=0," ",LOOKUP(A34,[1]COMPUTO!$A$14:$A$922,[1]COMPUTO!$K$14:$K$921)) | E34: =IF(A34=0," ",LOOKUP(A34,[1]ITEMS!$E$3:$E$106,[1]ITEMS!$D$3:$D$106)) | G34: =IF(A34=0,0,ROUND((D34*E34),2)) -> 0
B35: =IF(A35=0," ",LOOKUP(A35,[1]ITEMS!$E$3:$E$106,[1]ITEMS!$B$3:$B$106)) | C35: =IF(A35=0," ",LOOKUP(A35,[1]ITEMS!$E$3:$E$106,[1]ITEMS!$C$3:$C$106)) | D35: =IF(A35=0," ",LOOKUP(A35,[1]COMPUTO!$A$14:$A$922,[1]COMPUTO!$K$14:$K$921)) | E35: =IF(A35=0," ",LOOKUP(A35,[1]ITEMS!$E$3:$E$106,[1]ITEMS!$D$3:$D$106)) | G35: =IF(A35=0,0,ROUND((D35*E35),2)) -> 0
B36: =IF(A36=0," ",LOOKUP(A36,[1]ITEMS!$E$3:$E$106,[1]ITEMS!$B$3:$B$106)) | C36: =IF(A36=0," ",LOOKUP(A36,[1]ITEMS!$E$3:$E$106,[1]ITEMS!$C$3:$C$106)) | D36: =IF(A36=0," ",LOOKUP(A36,[1]COMPUTO!$A$14:$A$922,[1]COMPUTO!$K$14:$K$921)) | E36: =IF(A36=0," ",LOOKUP(A36,[1]ITEMS!$E$3:$E$106,[1]ITEMS!$D$3:$D$106)) | G36: =IF(A36=0,0,ROUND((D36*E36),2)) -> 0
B37: =IF(A37=0," ",LOOKUP(A37,[1]ITEMS!$E$3:$E$106,[1]ITEMS!$B$3:$B$106)) | C37: =IF(A37=0," ",LOOKUP(A37,[1]ITEMS!$E$3:$E$106,[1]ITEMS!$C$3:$C$106)) | D37: =IF(A37=0," ",LOOKUP(A37,[1]COMPUTO!$A$14:$A$922,[1]COMPUTO!$K$14:$K$921)) | E37: =IF(A37=0," ",LOOKUP(A37,[1]ITEMS!$E$3:$E$106,[1]ITEMS!$D$3:$D$106)) | G37: =IF(A37=0,0,ROUND((D37*E37),2)) -> 0
B38: =IF(A38=0," ",LOOKUP(A38,[1]ITEMS!$E$3:$E$106,[1]ITEMS!$B$3:$B$106)) | C38: =IF(A38=0," ",LOOKUP(A38,[1]ITEMS!$E$3:$E$106,[1]ITEMS!$C$3:$C$106)) | D38: =IF(A38=0," ",LOOKUP(A38,[1]COMPUTO!$A$14:$A$922,[1]COMPUTO!$K$14:$K$921)) | E38: =IF(A38=0," ",LOOKUP(A38,[1]ITEMS!$E$3:$E$106,[1]ITEMS!$D$3:$D$106)) | G38: =IF(A38=0,0,ROUND((D38*E38),2)) -> 0
B39: =IF(A39=0," ",LOOKUP(A39,[1]ITEMS!$E$3:$E$106,[1]ITEMS!$B$3:$B$106)) | C39: =IF(A39=0," ",LOOKUP(A39,[1]ITEMS!$E$3:$E$106,[1]ITEMS!$C$3:$C$106)) | D39: =IF(A39=0," ",LOOKUP(A39,[1]COMPUTO!$A$14:$A$922,[1]COMPUTO!$K$14:$K$921)) | E39: =IF(A39=0," ",LOOKUP(A39,[1]ITEMS!$E$3:$E$106,[1]ITEMS!$D$3:$D$106)) | G39: =IF(A39=0,0,ROUND((D39*E39),2)) -> 0
B40: =IF(A40=0," ",LOOKUP(A40,[1]ITEMS!$E$3:$E$106,[1]ITEMS!$B$3:$B$106)) | C40: =IF(A40=0," ",LOOKUP(A40,[1]ITEMS!$E$3:$E$106,[1]ITEMS!$C$3:$C$106)) | D40: =IF(A40=0," ",LOOKUP(A40,[1]COMPUTO!$A$14:$A$922,[1]COMPUTO!$K$14:$K$921)) | E40: =IF(A40=0," ",LOOKUP(A40,[1]ITEMS!$E$3:$E$106,[1]ITEMS!$D$3:$D$106)) | G40: =IF(A40=0,0,ROUND((D40*E40),2)) -> 0
B41: =IF(A41=0," ",LOOKUP(A41,[1]ITEMS!$E$3:$E$106,[1]ITEMS!$B$3:$B$106)) | C41: =IF(A41=0," ",LOOKUP(A41,[1]ITEMS!$E$3:$E$106,[1]ITEMS!$C$3:$C$106)) | D41: =IF(A41=0," ",LOOKUP(A41,[1]COMPUTO!$A$14:$A$922,[1]COMPUTO!$K$14:$K$921)) | E41: =IF(A41=0," ",LOOKUP(A41,[1]ITEMS!$E$3:$E$106,[1]ITEMS!$D$3:$D$106)) | G41: =IF(A41=0,0,ROUND((D41*E41),2)) -> 0
... B48: =IF(A48=0," ",LOOKUP(A48,[1]ITEMS!$E$3:$E$106,[1]ITEMS!$B$3:$B$106)) | C48: =IF(A48=0," ",LOOKUP(A48,[1]ITEMS!$E$3:$E$106,[1]ITEMS!$C$3:$C$106)) | D48: =IF(A48=0," ",LOOKUP(A48,[1]COMPUTO!$A$14:$A$922,[1]COMPUTO!$K$14:$K$921)) | E48: =IF(A48=0," ",LOOKUP(A48,[1]ITEMS!$E$3:$E$106,[1]ITEMS!$D$3:$D$106)) | G48: =IF(A48=0,0,ROUND((D48*E48),2)) -> 0
F49: PARCIAL | G49: =ROUND(SUM(G14:G48),2) -> 2575.8
F50: PARCIAL (AREA ESTRUCTURAL)
...

Sheet COMPUTO
A2: PLANILLA DE COMPUTOS METRICOS
A5: ="PROYECTO: "&DATOS!C2 -> PROYECTO: RELEVAMIENTO DE VIVIENDA
A7: ="LOCALIZACION:"&DATOS!D2 -> LOCALIZACION:ARGENTINA | F7: =""&DATOS!C13 -> AREA ARQUITECTURA
A8: ="DISTRITO:"&DATOS!E2 -> DISTRITO:RIO NEGRO
A11: ITEM | B11: D E S C R I P C I O N | C11: UNIDAD | D11: CANT. | E11: D I M E N S I O N E S | J11: COMPUTO | K11: COMPUTO
E12: LARGO | F12: ANCHO | G12: ALTO | H12: AREA | I12: VOLUMEN | J12: PARCIAL | K12: TOTAL
B13: INFRAESTRUCTURA
A14: 1 | B14: =IF(A14=0," ",LOOKUP(A14,ITEMS!$E$3:$E$106,ITEMS!$B$3:$B$106)) -> EXCAVACIÓN C/MAQ (INCLUYE CARG. Y TRANSP. ÁREA DE LA OBRA) | C14: =IF(A14=0," ",LOOKUP(A14,ITEMS!$E$3:$E$106,ITEMS!$C$3:$C$106)) -> M3 | K14: =SUM(J15:J16) -> 1
D15: 1 | J15: =+D15 -> 1
A17: 2 | B17: =IF(A17=0," ",LOOKUP(A17,ITEMS!$E$3:$E$106,ITEMS!$B$3:$B$106)) -> DESENLOSETADO | C17: =IF(A17=0," ",LOOKUP(A17,ITEMS!$E$3:$E$106,ITEMS!$C$3:$C$106)) -> M2 | K17: =SUM(J18:J19) -> 1
D18: 1 | J18: =+D18 -> 1
A20: 3 | B20: =IF(A20=0," ",LOOKUP(A20,ITEMS!$E$3:$E$106,ITEMS!$B$3:$B$106)) -> VENTANA DE MADERA ROBLE 2" | C20: =IF(A20=0," ",LOOKUP(A20,ITEMS!$E$3:$E$106,ITEMS!$C$3:$C$106)) -> M2 | K20: =SUM(J21:J22) -> 1
B21: } | D21: 1 | J21: =+D21 -> 1
A23: 4 | B23: =IF(A23=0," ",LOOKUP(A23,ITEMS!$E$3:$E$106,ITEMS!$B$3:$B$106)) -> ACERA DE CEMENTO E=10 CM SIN EMPEDRADO | C23: =IF(A23=0," ",LOOKUP(A23,ITEMS!$E$3:$E$106,ITEMS!$C$3:$C$106)) -> M2 | K23: =SUM(J24:J25) -> 1
D24: 1 | J24: =+D24 -> 1
A26: 5 | B26: =IF(A26=0," ",LOOKUP(A26,ITEMS!$E$3:$E$106,ITEMS!$B$3:$B$106)) -> VALVULA DE GAS D=2" PARA AN (PROV. E INST.) | C26: =IF(A26=0," ",LOOKUP(A26,ITEMS!$E$3:$E$106,ITEMS!$C$3:$C$106)) -> PZA | K26: =SUM(J27:J28) -> 1
D27: 1 | J27: =+D27 -> 1
A29: 6 | B29: =IF(A29=0," ",LOOKUP(A29,ITEMS!$E$3:$E$106,ITEMS!$B$3:$B$106)) -> Y PVC CLASE 9 D=4" (PROV. Y COLOC.) | C29: =IF(A29=0," ",LOOKUP(A29,ITEMS!$E$3:$E$106,ITEMS!$C$3:$C$106)) -> PZA | K29: =SUM(J30:J31) -> 1
D30: 1 | J30: =+D30 -> 1
A32: 7 | B32: =IF(A32=0," ",LOOKUP(A32,ITEMS!$E$3:$E$106,ITEMS!$B$3:$B$106)) -> PINTURA EN INTERIORES LATEX O SIMILARES (DOS MANOS) | C32: =IF(A32=0," ",LOOKUP(A32,ITEMS!$E$3:$E$106,ITEMS!$C$3:$C$106)) -> M2 | K32: =SUM(J33:J34) -> 1
D33: 1 | J33: =+D33 -> 1
A35: 8 | B35: =IF(A35=0," ",LOOKUP(A35,ITEMS!$E$3:$E$106,ITEMS!$B$3:$B$106)) -> PICADO REVOQUE DE CEMENTO | C35: =IF(A35=0," ",LOOKUP(A35,ITEMS!$E$3:$E$106,ITEMS!$C$3:$C$106)) -> M2 | K35: =SUM(J36:J37) -> 1
D36: 1 | J36: =+D36 -> 1
A38: 9 | B38: =IF(A38=0," ",LOOKUP(A38,ITEMS!$E$3:$E$106,ITEMS!$B$3:$B$106)) -> CABLE COBRE AISLADO 7 H Nº 8 AWG TW (PROV. E INST.) | C38: =IF(A38=0," ",LOOKUP(A38,ITEMS!$E$3:$E$106,ITEMS!$C$3:$C$106)) -> ML | K38: =SUM(J39:J40) -> 1
D39: 1 | J39: =+D39 -> 1
A41: 10 | B41: =IF(A41=0," ",LOOKUP(A41,ITEMS!$E$3:$E$106,ITEMS!$B$3:$B$106)) -> VENTILADOR DE 300 M3/H | C41: =IF(A41=0," ",LOOKUP(A41,ITEMS!$E$3:$E$106,ITEMS!$C$3:$C$106)) -> PZA | K41: =SUM(J42:J43) -> 1
D42: 1 | J42: =+D42 -> 1
A44: 11 | B44: =IF(A44=0," ",LOOKUP(A44,ITEMS!$E$3:$E$106,ITEMS!$B$3:$B$106)) -> INSTALACION CESPED SINTETICO H=50 MM | C44: =IF(A44=0," ",LOOKUP(A44,ITEMS!$E$3:$E$106,ITEMS!$C$3:$C$106)) -> M2 | K44: =SUM(J45:J46) -> 1
D45: 1 | J45: =+D45 -> 1
A47: 12 | B47: =IF(A47=0," ",LOOKUP(A47,ITEMS!$E$3:$E$106,ITEMS!$B$3:$B$106)) -> CANALETA DE CALAMINA PLANA N°28 CORTE 60 EN LIMAHOYA | C47: =IF(A47=0," ",LOOKUP(A47,ITEMS!$E$3:$E$106,ITEMS!$C$3:$C$106)) -> ML | K47: =SUM(J48:J49) -> 1
D48: 1 | J48: =+D48 -> 1
B50: =IF(A50=0," ",LOOKUP(A50,ITEMS!$E$3:$E$106,ITEMS!$B$3:$B$106)) | C50: =IF(A50=0," ",LOOKUP(A50,ITEMS!$E$3:$E$106,ITEMS!$C$3:$C$106)) | K50: =SUM(J51:J52) -> 1
D51: 1 | J51: =+D51 -> 1
B53: =IF(A53=0," ",LOOKUP(A53,ITEMS!$E$3:$E$106,ITEMS!$B$3:$B$106)) | C53: =IF(A53=0," ",LOOKUP(A53,ITEMS!$E$3:$E$106,ITEMS!$C$3:$C$106)) | K53: =SUM(J54:J55) -> 1
D54: 1 | J54: =+D54 -> 1
B56: =IF(A56=0," ",LOOKUP(A56,ITEMS!$E$3:$E$106,ITEMS!$B$3:$B$106)) | C56: =IF(A56=0," ",LOOKUP(A56,ITEMS!$E$3:$E$106,ITEMS!$C$3:$C$106)) | K56: =SUM(J57:J58) -> 1
D57: 1 | J57: =+D57 -> 1
B59: =IF(A59=0," ",LOOKUP(A59,ITEMS!$E$3:$E$106,ITEMS!$B$3:$B$106)) | C59: =IF(A59=0," ",LOOKUP(A59,ITEMS!$E$3:$E$106,ITEMS!$C$3:$C$106)) | K59: =SUM(J60:J61) -> 1
D60: 1 | J60: =+D60 -> 1
B62: =IF(A62=0," ",LOOKUP(A62,ITEMS!$E$3:$E$106,ITEMS!$B$3:$B$106)) | C62: =IF(A62=0," ",LOOKUP(A62,ITEMS!$E$3:$E$106,ITEMS!$C$3:$C$106)) | K62: =SUM(J63:J64) -> 1
...

Sheet CRONOG
A3: CRONOGRAMA DE EJECUCION DE OBRA | L3: TIEMPO DE EJECUCION | U3: 65 | Y3: D/C
A5: ="PROYECTO: "&DATOS!C2 -> PROYECTO: RELEVAMIENTO DE VIVIENDA
A7: ="LOCALIZACION: "&DATOS!D2 -> LOCALIZACION: ARGENTINA | G7: =""&DATOS!C13 -> AREA ARQUITECTURA
A8: ="DISTRITO: "&DATOS!E2 -> DISTRITO: RIO NEGRO
C11: DIAS | D11: 1 | K11: 2 | R11: 3 | Y11: 4 | AF11: 5 | AM11: 6 | AT11: 7 | BA11: 8 | BH11: 9 | BO11: 10 | BV11: 11 | CC11: 12 | CJ11: 13 | CQ11: 14 | CX11: 15
A12: No ÍTEM | B12: DESCRIPCIÓN DE LOS ÍTEMS | D12: 1 | E12: 2 | F12: 3 | G12: 4 | H12: 5 | I12: 6 | J12: 7 | K12: 8 | L12: 9 | M12: 10 | N12: 11 | O12: 12 | P12: 13 | Q12: 14 | R12: 15 | S12: 16 | T12: 17 | U12: 18 | V12: 19 | W12: 20 | X12: 21 | Y12: 22 | Z12: 23 | AA12: 24 | AB12: 25 | AC12: 26 | AD12: 27 | AE12: 28 | AF12: 29 | AG12: 30 | AH12: 31 | AI12: 32 | AJ12: 33 | AK12: 34 | AL12: 35 | AM12: 36 | AN12: 37 | AO12: 38 | AP12: 39 | AQ12: 40 | AR12: 41 | AS12: 42 | AT12: 43 | AU12: 44 | AV12: 45 | AW12: 46 | AX12: 47 | AY12: 48 | AZ12: 49 | BA12: 50 | BB12: 51 | BC12: 52 | BD12: 53 | BE12: 54 | BF12: 55 | BG12: 56 | BH12: 57 | BI12: 58 | BJ12: 59 | BK12: 60 | BL12: 61 | BM12: 62 | BN12: 63 | BO12: 64 | BP12: 65 | BQ12: 66 | BR12: 67 | BS12: 68 | BT12: 69 | BU12: 70 | BV12: 71 | BW12: 72 | BX12: 73 | BY12: 74 | BZ12: 75 | CA12: 76 | CB12: 77 | CC12: 78 | CD12: 79 | CE12: 80 | CF12: 81 | CG12: 82 | CH12: 83 | CI12: 84 | CJ12: 85 | CK12: 86 | CL12: 87 | CM12: 88 | CN12: 89 | CO12: 90 | CP12: 91 | CQ12: 92 | CR12: 93 | CS12: 94 | CT12: 95 | CU12: 96 | CV12: 97 | CW12: 98 | CX12: 99 | CY12: 100 | CZ12: 101 | DA12: 102 | DB12: 103 | DC12: 104 | DD12: 105
B13: ARQUITECTURA
B14: =IF(A14=0,'B1 '!B13," ") -> MOVIMIENTO DE TIERRAS
A15: 1 | B15: =IF(A15=0," ",ITEMS!B3) -> EXCAVACIÓN C/MAQ (INCLUYE CARG. Y TRANSP. ÁREA DE LA OBRA) | C15: =SUM(D15:DR15) -> 11 | D15: 1 | E15: 1 | F15: 1 | G15: 1 | H15: 1 | I15: 1 | J15: 1 | K15: 1 | L15: 1 | M15: 1 | N15: 1
A16: 2 | B16: =IF(A16=0," ",ITEMS!B4) -> DESENLOSETADO | C16: 10
A17: 3 | B17: =IF(A17=0," ",ITEMS!B5) -> VENTANA DE MADERA ROBLE 2" | C17: =SUM(D17:DR17) -> 0
A18: 4 | B18: =IF(A18=0," ",ITEMS!B6) -> ACERA DE CEMENTO E=10 CM SIN EMPEDRADO | C18: =SUM(D18:DR18) -> 0
A19: 5 | B19: =IF(A19=0," ",ITEMS!B7) -> VALVULA DE GAS D=2" PARA AN (PROV. E INST.) | C19: =SUM(D19:DR19) -> 0
A20: 6 | B20: =IF(A20=0," ",ITEMS!B8) -> Y PVC CLASE 9 D=4" (PROV. Y COLOC.) | C20: =SUM(D20:DR20) -> 0
A21: 7 | B21: =IF(A21=0," ",ITEMS!B9) -> PINTURA EN INTERIORES LATEX O SIMILARES (DOS MANOS) | C21: =SUM(D21:DR21) -> 5 | L21: 1 | M21: 1 | N21: 1 | O21: 1 | P21: 1
A22: 8 | B22: =IF(A22=0," ",ITEMS!B10) -> PICADO REVOQUE DE CEMENTO | C22: =SUM(D22:DR22) -> 1 | BY22: 1
A23: 9 | B23: =IF(A23=0," ",ITEMS!B11) -> CABLE COBRE AISLADO 7 H Nº 8 AWG TW (PROV. E INST.) | C23: =SUM(D23:DR23) -> 0
A24: 10 | B24: =IF(A24=0," ",ITEMS!B12) -> VENTILADOR DE 300 M3/H | C24: =SUM(D24:DR24) -> 0
A25: 11 | B25: =IF(A25=0," ",ITEMS!B13) -> INSTALACION CESPED SINTETICO H=50 MM | C25: =SUM(D25:DR25) -> 0
A26: 12 | B26: =IF(A26=0," ",ITEMS!B14) -> CANALETA DE CALAMINA PLANA N°28 CORTE 60 EN LIMAHOYA | C26: =SUM(D26:DR26) -> 0
A27: 13 | B27: =IF(A27=0," ",ITEMS!B15) | C27: =SUM(D27:DR27) -> 0
A28: 14 | B28: =IF(A28=0," ",ITEMS!B16) | C28: =SUM(D28:DR28) -> 0
A29: 15 | B29: =IF(A29=0," ",ITEMS!B17) | C29: =SUM(D29:DR29) -> 0
A30: 16 | B30: =IF(A30=0," ",ITEMS!B18) | C30: =SUM(D30:DR30) -> 0
A31: 17 | B31: =IF(A31=0," ",ITEMS!B19) | C31: =SUM(D31:DR31) -> 0

Sheet BD
B2: BASE DE DATOS 2026 - OBRAS MENORES
B3: Moneda en Pesos.-
A5: AREA | B5: ITEM | C5: DESCRIPCIÓN | D5: UND. | E5: PRECIO UNITARIO | F5: PLIEGO DE ESPECIFICACIONES TECNICAS | G5: OBS.
A7: ARQU | B7: 1 | C7: ACERA DE CEMENTO E=10 CM CON EMPEDRADO | D7: M2 | E7: 287.58 | F7: =HYPERLINK(I7) -> C:\PETS_2016\1_AREA ARQ\ARQ 001.DOCX | I7: =CONCATENATE(K7,M7,O7,Q7) -> C:\PETS_2016\1_AREA ARQ\ARQ 001.DOCX | K7: C:\PETS_2016\1_AREA ARQ | M7: \ | O7: ARQ 001 | Q7: .DOCX | R7: "
A8: ARQU | B8: =+B7+1 -> 2 | C8: ACERA DE CEMENTO E=10 CM SIN EMPEDRADO | D8: M2 | E8: 155.42 | F8: =HYPERLINK(I8) -> C:\PETS_2016\1_AREA ARQ\ARQ 002.DOCX | I8: =CONCATENATE(K8,M8,O8,Q8) -> C:\PETS_2016\1_AREA ARQ\ARQ 002.DOCX | K8: C:\PETS_2016\1_AREA ARQ | M8: \ | O8: ARQ 002 | Q8: .DOCX | R8: "
A9: ARQU | B9: =+B8+1 -> 3 | C9: ACERA DE CEMENTO E=5 CM CON EMPEDRADO | D9: M2 | E9: 153.26 | F9: =HYPERLINK(I9) -> C:\PETS_2016\1_AREA ARQ\ARQ 003.DOCX | I9: =CONCATENATE(K9,M9,O9,Q9) -> C:\PETS_2016\1_AREA ARQ\ARQ 003.DOCX | K9: C:\PETS_2016\1_AREA ARQ | M9: \ | O9: ARQ 003 | Q9: .DOCX | R9: "
A10: ARQU | B10: =+B9+1 -> 4 | C10: ACERA DE CEMENTO E=5 CM SIN EMPEDRADO | D10: M2 | E10: 78.15 | F10: =HYPERLINK(I10) -> C:\PETS_2016\1_AREA ARQ\ARQ 004.DOCX | I10: =CONCATENATE(K10,M10,O10,Q10) -> C:\PETS_2016\1_AREA ARQ\ARQ 004.DOCX | K10: C:\PETS_2016\1_AREA ARQ | M10: \ | O10: ARQ 004 | Q10: .DOCX | R10: "
A11: ARQU | B11: =+B10+1 -> 5 | C11: ACERA DE CEMENTO E=7,5 CM CON EMPEDRADO | D11: M2 | E11: 216.29 | F11: =HYPERLINK(I11) -> C:\PETS_2016\1_AREA ARQ\ARQ 005.DOCX | I11: =CONCATENATE(K11,M11,O11,Q11) -> C:\PETS_2016\1_AREA ARQ\ARQ 005.DOCX | K11: C:\PETS_2016\1_AREA ARQ | M11: \ | O11: ARQ 005 | Q11: .DOCX | R11: "
A12: ARQU | B12: =+B11+1 -> 6 | C12: ACERA DE CEMENTO E=7,5 CM SIN EMPEDRADO | D12: M2 | E12: 131.05 | F12: =HYPERLINK(I12) -> C:\PETS_2016\1_AREA ARQ\ARQ 006.DOCX | I12: =CONCATENATE(K12,M12,O12,Q12) -> C:\PETS_2016\1_AREA ARQ\ARQ 006.DOCX | K12: C:\PETS_2016\1_AREA ARQ | M12: \ | O12: ARQ 006 | Q12: .DOCX | R12: "
A13: ARQU | B13: =+B12+1 -> 7 | C13: ALEROS | D13: M2 | E13: 337.13 | F13: =HYPERLINK(I13) -> C:\PETS_2016\1_AREA ARQ\ARQ 007.DOCX | I13: =CONCATENATE(K13,M13,O13,Q13) -> C:\PETS_2016\1_AREA ARQ\ARQ 007.DOCX | K13: C:\PETS_2016\1_AREA ARQ | M13: \ | O13: ARQ 007 | Q13: .DOCX | R13: "
A14: ARQU | B14: =+B13+1 -> 8 | C14: ARCO C/EST. MET. P/TABLERO PROF. BASQUET (PROV. Y COLOC.) | D14: PZA | E14: 5262.08 | F14: =HYPERLINK(I14) -> C:\PETS_2016\1_AREA ARQ\ARQ 008.DOCX | I14: =CONCATENATE(K14,M14,O14,Q14) -> C:\PETS_2016\1_AREA ARQ\ARQ 008.DOCX | K14: C:\PETS_2016\1_AREA ARQ | M14: \ | O14: ARQ 008 | Q14: .DOCX | R14: "
A15: ARQU | B15: =+B14+1 -> 9 | C15: ARCO Y TABLERO INTEGRADO (PROV. Y COLOC.) | D15: PZA | E15: 7638.27 | F15: =HYPERLINK(I15) -> C:\PETS_2016\1_AREA ARQ\ARQ 009.DOCX | I15: =CONCATENATE(K15,M15,O15,Q15) -> C:\PETS_2016\1_AREA ARQ\ARQ 009.DOCX | K15: C:\PETS_2016\1_AREA ARQ | M15: \ | O15: ARQ 009 | Q15: .DOCX | R15: "
A16: ARQU | B16: =+B15+1 -> 10 | C16: ARCOS DE FUTBOL TUBERIA FG D=4" | D16: PAR | E16: 5407.83 | F16: =HYPERLINK(I16) -> C:\PETS_2016\1_AREA ARQ\ARQ 010.DOCX | I16: =CONCATENATE(K16,M16,O16,Q16) -> C:\PETS_2016\1_AREA ARQ\ARQ 010.DOCX | K16: C:\PETS_2016\1_AREA ARQ | M16: \ | O16: ARQ 010 | Q16: .DOCX | R16: "
A17: ARQU | B17: =+B16+1 -> 11 | C17: AREA VERDE C/ TEPE | D17: M2 | E17: 80.37 | F17: =HYPERLINK(I17) -> C:\PETS_2016\1_AREA ARQ\ARQ 011.DOCX | I17: =CONCATENATE(K17,M17,O17,Q17) -> C:\PETS_2016\1_AREA ARQ\ARQ 011.DOCX | K17: C:\PETS_2016\1_AREA ARQ | M17: \ | O17: ARQ 011 | Q17: .DOCX | R17: "
A18: ARQU | B18: =+B17+1 -> 12 | C18: AREA VERDE C/CESPED DE ALTO TRAFICO | D18: M2 | E18: 174.66 | F18: =HYPERLINK(I18) -> C:\PETS_2016\1_AREA ARQ\ARQ 012.DOCX | I18: =CONCATENATE(K18,M18,O18,Q18) -> C:\PETS_2016\1_AREA ARQ\ARQ 012.DOCX | K18: C:\PETS_2016\1_AREA ARQ | M18: \ | O18: ARQ 012 | Q18: .DOCX | R18: "
A19: ARQU | B19: =+B18+1 -> 13 | C19: ARENA FINA P/CESPED SINTETICO | D19: M3 | E19: 207.85 | F19: =HYPERLINK(I19) -> C:\PETS_2016\1_AREA ARQ\ARQ 013.DOCX | I19: =CONCATENATE(K19,M19,O19,Q19) -> C:\PETS_2016\1_AREA ARQ\ARQ 013.DOCX | K19: C:\PETS_2016\1_AREA ARQ | M19: \ | O19: ARQ 013 | Q19: .DOCX | R19: "
... A477: ARQU | B477: =+B476+1 -> 471 | C477: ZOCALO DE VINIL H= 10 CM | D477: ML | E477: 35.78 | F477: =HYPERLINK(I477) -> C:\PETS_2016\1_AREA ARQ\ARQ 471.DOCX | I477: =CONCATENATE(K477,M477,O477,Q477) -> C:\PETS_2016\1_AREA ARQ\ARQ 471.DOCX | K477: C:\PETS_2016\1_AREA ARQ | M477: \ | O477: ARQ 471 | Q477: .DOCX | R477: "
A478: ESTRUC | B478: =+B477+1 -> 472 | C478: ABACO DE HORMIGON ARMADO PARA ENTREPISO | D478: M3 | E478: 4931.15 | F478: =HYPERLINK(J478) -> C:\PETS_2016\5_AREA ESTRUC\EST 001.DOCX | J478: =CONCATENATE(L478,M478,O478,Q478) -> C:\PETS_2016\5_AREA ESTRUC\EST 001.DOCX | L478: C:\PETS_2016\5_AREA ESTRUC | M478: \ | O478: EST 001 | Q478: .DOCX | R478: "
A479: ESTRUC | B479: =+B478+1 -> 473 | C479: ÁBACOS DE HORMIGON PREMEZCLADO H-25 | D479: M3 | E479: 2457.91 | F479: =HYPERLINK(J479) -> C:\PETS_2016\5_AREA ESTRUC\EST 002.DOCX | J479: =CONCATENATE(L479,M479,O479,Q479) -> C:\PETS_2016\5_AREA ESTRUC\EST 002.DOCX | L479: C:\PETS_2016\5_AREA ESTRUC | M479: \ | O479: EST 002 | Q479: .DOCX | R479: "
A480: ESTRUC | B480: =+B479+1 -> 474 | C480: ACERO ASTM A615-60 | D480: KG | E480: 13.53 | F480: =HYPERLINK(J480) -> C:\PETS_2016\5_AREA ESTRUC\EST 003.DOCX | J480: =CONCATENATE(L480,M480,O480,Q480) -> C:\PETS_2016\5_AREA ESTRUC\EST 003.DOCX | L480: C:\PETS_2016\5_AREA ESTRUC | M480: \ | O480: EST 003 | Q480: .DOCX | R480: "
A481: ESTRUC | B481: =+B480+1 -> 475 | C481: ACERO DE REFUERZO | D481: KG | E481: 23.27 | F481: =HYPERLINK(J481) -> C:\PETS_2016\5_AREA ESTRUC\EST 004.DOCX | J481: =CONCATENATE(L481,M481,O481,Q481) -> C:\PETS_2016\5_AREA ESTRUC\EST 004.DOCX | L481: C:\PETS_2016\5_AREA ESTRUC | M481: \ | O481: EST 004 | Q481: .DOCX | R481: "
A482: ESTRUC | B482: =+B481+1 -> 476 | C482: ADHESIVO EPÓXICO P/ANCLAJE | D482: M2 | E482: 357.04 | F482: =HYPERLINK(J482) -> C:\PETS_2016\5_AREA ESTRUC\EST 005.DOCX | J482: =CONCATENATE(L482,M482,O482,Q482) -> C:\PETS_2016\5_AREA ESTRUC\EST 005.DOCX | L482: C:\PETS_2016\5_AREA ESTRUC | M482: \ | O482: EST 005 | Q482: .DOCX | R482: "
A483: ESTRUC | B483: =+B482+1 -> 477 | C483: AGOTAMIENTO PARA NIVEL FREÁTICO | D483: HR | E483: 97.65 | F483: =HYPERLINK(J483) -> C:\PETS_2016\5_AREA ESTRUC\EST 006.DOCX | J483: =CONCATENATE(L483,M483,O483,Q483) -> C:\PETS_2016\5_AREA ESTRUC\EST 006.DOCX | L483: C:\PETS_2016\5_AREA ESTRUC | M483: \ | O483: EST 006 | Q483: .DOCX | R483: "
A484: ESTRUC | B484: =+B483+1 -> 478 | C484: ANCLAJE MONOTORONES DE 1/2" C/CUÑAS F500SL2 SURE LOCK | D484: PZA | E484: 87.15 | F484: =HYPERLINK(J484) -> C:\PETS_2016\5_AREA ESTRUC\EST 007.DOCX | J484: =CONCATENATE(L484,M484,O484,Q484) -> C:\PETS_2016\5_AREA ESTRUC\EST 007.DOCX | L484: C:\PETS_2016\5_AREA ESTRUC | M484: \ | O484: EST 007 | Q484: .DOCX | R484: "
A485: ESTRUC | B485: =+B484+1 -> 479 | C485: ANCLAJE P/ESTRUCTURA METALICA (CUBIERTA) | D485: PZA | E485: 281.13 | F485: =HYPERLINK(J485) -> C:\PETS_2016\5_AREA ESTRUC\EST 008.DOCX | J485: =CONCATENATE(L485,M485,O485,Q485) -> C:\PETS_2016\5_AREA ESTRUC\EST 008.DOCX | L485: C:\PETS_2016\5_AREA ESTRUC | M485: \ | O485: EST 008 | Q485: .DOCX | R485: "
A486: ESTRUC | B486: =+B485+1 -> 480 | C486: ANCLAJE P/ESTRUCTURA METÁLICA (PÓRTICO, PASARELA) | D486: PZA | E486: 742.64 | F486: =HYPERLINK(J486) -> C:\PETS_2016\5_AREA ESTRUC\EST 009.DOCX | J486: =CONCATENATE(L486,M486,O486,Q486) -> C:\PETS_2016\5_AREA ESTRUC\EST 009.DOCX | L486: C:\PETS_2016\5_AREA ESTRUC | M486: \ | O486: EST 009 | Q486: .DOCX | R486: "
A487: ESTRUC | B487: =+B486+1 -> 481 | C487: BAJANTE DE CALAMINA PLANA Nº 28 | D487: ML | E487: 190.98 | F487: =HYPERLINK(J487) -> C:\PETS_2016\5_AREA ESTRUC\EST 010.DOCX | J487: =CONCATENATE(L487,M487,O487,Q487) -> C:\PETS_2016\5_AREA ESTRUC\EST 010.DOCX | L487: C:\PETS_2016\5_AREA ESTRUC | M487: \ | O487: EST 010 | Q487: .DOCX | R487: "
A488: ESTRUC | B488: =+B487+1 -> 482 | C488: BARANDADO TIPO P-3 (SUPERESTRUCTURA) | D488: ML | E488: 1024.24 | F488: =HYPERLINK(J488) -> C:\PETS_2016\5_AREA ESTRUC\EST 011.DOCX | J488: =CONCATENATE(L488,M488,O488,Q488) -> C:\PETS_2016\5_AREA ESTRUC\EST 011.DOCX | L488: C:\PETS_2016\5_AREA ESTRUC | M488: \ | O488: EST 011 | Q488: .DOCX | R488: "
A489: ESTRUC | B489: =+B488+1 -> 483 | C489: CABLE DE ACERO 1" (PROV. Y COLOC.) | D489: ML | E489: 288.71 | F489: =HYPERLINK(J489) -> C:\PETS_2016\5_AREA ESTRUC\EST 012.DOCX | J489: =CONCATENATE(L489,M489,O489,Q489) -> C:\PETS_2016\5_AREA ESTRUC\EST 012.DOCX | L489: C:\PETS_2016\5_AREA ESTRUC | M489: \ | O489: EST 012 | Q489: .DOCX | R489: "
... A612: ESTRUC | B612: =+B611+1 -> 606 | C612: PERFIL COSTANERA METÁLICA 150X50X15X2 MM | D612: ML | E612: 112.83 | F612: =HYPERLINK(J612) -> C:\PETS_2016\5_AREA ESTRUC\EST 135.DOCX | J612: =CONCATENATE(L612,M612,O612,Q612) -> C:\PETS_2016\5_AREA ESTRUC\EST 135.DOCX | L612: C:\PETS_2016\5_AREA ESTRUC | M612: \ | O612: EST 135 | Q612: .DOCX | R612: "
A613: ESTRUC | B613: =+B612+1 -> 607 | C613: PERFIL COSTANERA METALICA 200X50X15X3 MM | D613: ML | E613: 182.31 | F613: =HYPERLINK(J613) -> C:\PETS_2016\5_AREA ESTRUC\EST 136.DOCX | G613: JACHA UTA ESPECIAL | J613: =CONCATENATE(L613,M613,O613,Q613) -> C:\PETS_2016\5_AREA ESTRUC\EST 136.DOCX | L613: C:\PETS_2016\5_AREA ESTRUC | M613: \ | O613: EST 136 | Q613: .DOCX | R613: "
A614: ESTRUC | B614: =+B613+1 -> 608 | C614: PERFIL COSTANERA METÁLICA 50X25X12X2 MM | D614: ML | E614: 54.16 | F614: =HYPERLINK(J614) -> C:\PETS_2016\5_AREA ESTRUC\EST 137.DOCX | J614: =CONCATENATE(L614,M614,O614,Q614) -> C:\PETS_2016\5_AREA ESTRUC\EST 137.DOCX | L614: C:\PETS_2016\5_AREA ESTRUC | M614: \ | O614: EST 137 | Q614: .DOCX | R614: "
A615: ESTRUC | B615: =+B614+1 -> 609 | C615: PERFIL COSTANERA METÁLICA 80X40X15X2 MM | D615: ML | E615: 101.57 | F615: =HYPERLINK(J615) -> C:\PETS_2016\5_AREA ESTRUC\EST 138.DOCX | J615: =CONCATENATE(L615,M615,O615,Q615) -> C:\PETS_2016\5_AREA ESTRUC\EST 138.DOCX | L615: C:\PETS_2016\5_AREA ESTRUC | M615: \ | O615: EST 138 | Q615: .DOCX | R615: "
A616: ESTRUC | B616: =+B615+1 -> 610 | C616: PERFIL COSTANERA P/ESTRUCTURA METÁLICA | D616: KG | E616: 21.6 | F616: =HYPERLINK(J616) -> C:\PETS_2016\5_AREA ESTRUC\EST 139.DOCX | J616: =CONCATENATE(L616,M616,O616,Q616) -> C:\PETS_2016\5_AREA ESTRUC\EST 139.DOCX | L616: C:\PETS_2016\5_AREA ESTRUC | M616: \ | O616: EST 139 | Q616: .DOCX | R616: "
A617: ESTRUC | B617: =+B616+1 -> 611 | C617: PERFIL L-30,30,3 MM | D617: KG | E617: 16.79 | F617: =HYPERLINK(J617) -> C:\PETS_2016\5_AREA ESTRUC\EST 140.DOCX | J617: =CONCATENATE(L617,M617,O617,Q617) -> C:\PETS_2016\5_AREA ESTRUC\EST 140.DOCX | L617: C:\PETS_2016\5_AREA ESTRUC | M617: \ | O617: EST 140 | Q617: .DOCX | R617: "
A618: ESTRUC | B618: =+B617+1 -> 612 | C618: PERFIL L-50,50,5 MM. | D618: KG | E618: 16.79 | F618: =HYPERLINK(J618) -> C:\PETS_2016\5_AREA ESTRUC\EST 141.DOCX | J618: =CONCATENATE(L618,M618,O618,Q618) -> C:\PETS_2016\5_AREA ESTRUC\EST 141.DOCX | L618: C:\PETS_2016\5_AREA ESTRUC | M618: \ | O618: EST 141 | Q618: .DOCX | R618: "
A619: ESTRUC | B619: =+B618+1 -> 613 | C619: PERFIL L-60,60,6 MM. | D619: KG | E619: 16.79 | F619: =HYPERLINK(J619) -> C:\PETS_2016\5_AREA ESTRUC\EST 142.DOCX | J619: =CONCATENATE(L619,M619,O619,Q619) -> C:\PETS_2016\5_AREA ESTRUC\EST 142.DOCX | L619: C:\PETS_2016\5_AREA ESTRUC | M619: \ | O619: EST 142 | Q619: .DOCX | R619: "
A620: ESTRUC | B620: =+B619+1 -> 614 | C620: PICADO Y PERFORADO EN HORMIGON ARMADO | D620: M3 | E620: 386.33 | F620: =HYPERLINK(J620) -> C:\PETS_2016\5_AREA ESTRUC\EST 143.DOCX | J620: =CONCATENATE(L620,M620,O620,Q620) -> C:\PETS_2016\5_AREA ESTRUC\EST 143.DOCX | L620: C:\PETS_2016\5_AREA ESTRUC | M620: \ | O620: EST 143 | Q620: .DOCX | R620: "
A621: ESTRUC | B621: =+B620+1 -> 615 | C621: PILOTES IN SITU DE HºAº; DN=1.00 M (INFRAESTRUCTURA) | D621: ML | E621: 5380.74 | F621: =HYPERLINK(J621) -> C:\PETS_2016\5_AREA ESTRUC\EST 144.DOCX | J621: =CONCATENATE(L621,M621,O621,Q621) -> C:\PETS_2016\5_AREA ESTRUC\EST 144.DOCX | L621: C:\PETS_2016\5_AREA ESTRUC | M621: \ | O621: EST 144 | Q621: .DOCX | R621: "
A622: ESTRUC | B622: =+B621+1 -> 616 | C622: PILOTES IN SITU DE HºAº; DN=1.20 M (INFRAESTRUCTURA) | D622: ML | E622: 6428.23 | F622: =HYPERLINK(J622) -> C:\PETS_2016\5_AREA ESTRUC\EST 145.DOCX | J622: =CONCATENATE(L622,M622,O622,Q622) -> C:\PETS_2016\5_AREA ESTRUC\EST 145.DOCX | L622: C:\PETS_2016\5_AREA ESTRUC | M622: \ | O622: EST 145 | Q622: .DOCX | R622: "
...

Sheet ACTA
A2: ACTA DE CONFORMIDAD
A4: DIRECCION DE PROYECTOS MUNICIPALES
A28: CODIDO SISIN: | D28: =DATOS!B2 -> 1005-4984-0000
A29: PROYECTO: | D29: =DATOS!C2 -> RELEVAMIENTO DE VIVIENDA
A31: AREA PROYECTADA:
A32: MONTO POA 2015:
A33: TIEMPO DE EJECUCION: | D33: =DATOS!C29 -> 65
A53: AL Pie del presente, firman para fines consiguientes:
C57: DIRECTOR | G57: SUB ALCALDE DE DISTRITO
C62: JEFE DE UNIDAD | G62: PRESIDENTE DE JUNTA VECINAL
C67: PROYECTISTA | G67: COMITÉ DE VIGILANCIA
A68: C.C./Arch.
A69: C.C./DPM.

Sheet FECHA
C2: FECHA Y HORA ACTUAL | D2: =NOW() -> 46209.868
C3: DIA | D3: =DAY(D2) -> 6
C4: MES | D4: =MONTH(D2) -> 7 | E4: =IF(D4=0," ",LOOKUP(D4,F9:F20,G9:G20)) -> Julio
C5: AÑO | D5: =YEAR(D2) -> 2026
C6: HORA | D6: =HOUR(D2) -> 20
C7: MINUTO | D7: =MINUTE(D2) -> 49
F9: 1 | G9: Enero
F10: 2 | G10: Febrero
F11: 3 | G11: Marzo
F12: 4 | G12: Abril
F13: 5 | G13: Mayo
F14: 6 | G14: Junio
F15: 7 | G15: Julio
F16: 8 | G16: Agosto
F17: 9 | G17: Septiembre
F18: 10 | G18: Octubre
F19: 11 | G19: Noviembre
F20: 12 | G20: Diciembre

Sheet Hoja2
A3: AREA | B3: Nº | C3: DESCRIPCION DEL ITEM | D3: UNIDAD | E3: CANTIDAD | F3: PRECIO UNITARIO | G3: PRECIO UNITARIO LITERAL | H3: PRECIOS PARCIALES | K3: TIPO DE OBRA | M3: BASE DE DATOS AREA ARQUITECTURA 2012 OMS | S3: BASE DE AREA DE INGENIERIA ESTRUCTURA OMS
A4: ARQUITECTURA | C4: INSTALACION DE FAENAS Y COLOCADO DE LETRERO | K4: ARQUITECTURA | L4: OBRAS PRELIMINARES | M4: Moneda en Bs.- | T4: Moneda: Bolivianos
K5: ESTRUCTURAL | L5: OBRA GRUESA
K6: SANITARIA | L6: OBRA FINA | Q6: PRECIO | W6: PRECIO
K7: ELECTRICA | L7: OBRAS COMPLEMENTARIAS | M7: ÍTEM | N7: DESCRIPCIÓN | O7: UND. | P7: CANTIDAD | Q7: UNITARIO | S7: ÍTEM | T7: DESCRIPCIÓN | U7: UND. | V7: CANTIDAD | W7: UNITARIO
L8: OBRA GRUESA | M8: 1 | N8: ACABADO GRANEADO A MAQUINA (PIRULEADO) | O8: M2 | P8: 1 | Q8: 44.74
L9: INFRAESTRUCTURA | M9: 2 | N9: ACERA DE CEMENTO 1:2:4 E=10 CM SIN CONTRAPISO | O9: M2 | P9: 1 | Q9: 122.3 | S9: 1 | T9: ABACO PARA ENTREPISO | U9: M3 | V9: 1 | W9: 3183.09
L10: SUPERESTRUCTURA | M10: 3 | N10: ACERA DE CEMENTO 1:2:4 E=10CM CON CONTRAPISO | O10: M2 | P10: 1 | Q10: 146.56 | S10: 2 | T10: ABACO PARA ENTREPISO CON ESPESOR DE 30CM | U10: M3 | V10: 1 | W10: 4153.37
L11: INSTALACION AGUA POTABLE | M11: 4 | N11: ACERA DE CEMENTO 1:2:4 E=5 CM CON CONTRAPISO | O11: M2 | P11: 1 | Q11: 113.93 | S11: 3 | T11: ADHESIVO EPOXICO P/ANCLAJE | U11: ML | V11: 1 | W11: 11.55
L12: INSTALACION SANITARIA | M12: 5 | N12: ACERA DE CEMENTO 1:2:4 E=7.5 CM CON CONTRAPISO | O12: M2 | P12: 1 | Q12: 122.68 | S12: 4 | T12: AGOTAMIENTO PARA NIVEL FREATICO | U12: HR | V12: 1 | W12: 48.67
L13: INSTALACION PLUVIAL | M13: 6 | N13: ACERA DE CEMENTO 1:2:4 E=7.5 CM SIN CONTRAPISO | O13: M2 | P13: 1 | Q13: 107.72 | S13: 5 | T13: ANCLAJE PARA ESTRUCTURA METALICA | U13: PZA | V13: 1 | W13: 562.35
L14: INSTALACION ELECTRICA | M14: 7 | N14: ACERA DE CONCRETO 1:2:4 E=5CM SIN CONTRAPISO | O14: M2 | P14: 1 | Q14: 93.38 | S14: 6 | T14: APOYO PERGOLA (TUB FE D=4"+PLANCHA METALICA) | U14: PZA | V14: 1 | W14: 1315.15
M15: 8 | N15: ALERO DE MACHIHEMBRE | O15: M2 | P15: 1 | Q15: 157.65 | S15: 7 | T15: APOYOS DE NEOPRENO COMPUESTO | U15: DM3 | V15: 1 | W15: 615.04
M16: 9 | N16: ALEROS | O16: M2 | P16: 1 | Q16: 209.72 | S16: 8 | T16: BAJANTE DE CALAMINA PLANA Nº 28 | U16: ML | V16: 1 | W16: 89.51
M17: 10 | N17: ALFOMBRA P/ALTO TRAFICO | O17: M2 | P17: 1 | Q17: 171.59 | S17: 9 | T17: BARRAS DE ACERO P/ESTRUCTURAS | U17: KG | V17: 1 | W17: 29.85
M18: 11 | N18: AREA VERDE EN JARDINES C/TEPE | O18: M2 | P18: 1 | Q18: 54.09 | S18: 10 | T18: CANALETA DE CALAMINA N° 28 CORTE 50 | U18: ML | V18: 1 | W18: 126.25
M19: 12 | N19: AREA VERDE EN PENDIENTE CON RAY GRASS | O19: M2 | P19: 1 | Q19: 79.32 | S19: 11 | T19: CORREAS METALICAS 100X50X15X2 | U19: M2 | V19: 1 | W19: 76.35
M20: 13 | N20: AREA VERDE P/JARDINES | O20: M2 | P20: 1 | Q20: 115.16 | S20: 12 | T20: CORREAS METALICAS 80 X 40 X 15 X 2 | U20: ML | V20: 1 | W20: 75.31
M21: 14 | N21: ARENA ESPECIAL PARA SUJECION | O21: M3 | P21: 1 | Q21: 171.86 | S21: 13 | T21: CORREAS METALICAS 80X40X15X2 | U21: M2 | V21: 1 | W21: 63.61
M22: 15 | N22: ASIENTO DE H°A° DOSIF 1:3:4 | O22: ML | P22: 1 | Q22: 353.42 | S22: 14 | T22: COSTANERA METALICA 100X50X15X2 | U22: ML | V22: 1 | W22: 62.76
M23: 16 | N23: ASIENTOS DE Hº Cº Y LADRILLO GAMBOTE 2 X 0.40 H = 0.40 M | O23: PZA | P23: 1 | Q23: 509.18 | S23: 15 | T23: COSTANERA METALICA 80X40X15X2MM | U23: ML | V23: 1 | W23: 98.34
M24: 17 | N24: ASIENTOS PLANOS DE HORMIGON ARMADO | O24: PZA | P24: 1 | Q24: 328.45 | S24: 16 | T24: CUBIERTA CALAMINA PLASTICA P/ ESTRUCTURA METALICA | U24: M2 | V24: 1 | W24: 204.42
M25: 18 | N25: BAJANTE DE CALAMINA PLANA Nº 28 D=4" | O25: ML | P25: 1 | Q25: 82.35 | S25: 17 | T25: CUBIERTA CON TEJA SHINGLE INCLUYE CERCHAS Y CORREAS | U25: M2 | V25: 1 | W25: 427.71
M26: 19 | N26: BAJANTE DE TUBERIA PVC DE 4" (TUBERIA CLASE 9) | O26: ML | P26: 1 | Q26: 73.59 | S26: 18 | T26: CUBIERTA DE CALAMINA GALVANIZADA Nº28+EST. MET. PERFIL COST. | U26: M2 | V26: 1 | W26: 613.13
... M116: 109 | N116: CUMBRERA DE CALAMINA PLANA GALVANIZADA Nº 28 | O116: ML | P116: 1 | Q116: 80.58 | S116: 108 | T116: TUBOS DE FG 2" P/CERCHA | U116: ML | V116: 1 | W116: 177.71
M117: 110 | N117: CUMBRERA FIJA PLACA ONDULADA (FIBROCEMENTO) | O117: M2 | P117: 1 | Q117: 69.6
M118: 111 | N118: CUMBRERA TEJA COLONIAL | O118: ML | P118: 1 | Q118: 59.21
M119: 112 | N119: CUNETA HºCº PARA CANCHA + IMPERMEABILIZACION EN INTERIOR | O119: M3 | P119: 1 | Q119: 1002.97
M120: 113 | N120: DEMOLICION DE CIMIENTOS CERCO DE MALLA OLÍMPICA | O120: M3 | P120: 1 | Q120: 156.6
M121: 114 | N121: DEMOLICION DE CONCRETO DE 0.5 A 10 M DE ESPESOR | O121: M2 | P121: 1 | Q121: 20.82
M122: 115 | N122: DEMOLICION DE CONCRETO DE 3 A 5 CM DE ESP CON COMBO Y BARR | O122: M2 | P122: 1 | Q122: 18.04
M123: 116 | N123: DEMOLICION DE CORDON DE ACERA | O123: ML | P123: 1 | Q123: 16.65
M124: 117 | N124: DEMOLICION DE HORMIGON ARMADO | O124: M3 | P124: 1 | Q124: 194.28
M125: 118 | N125: DEMOLICION DE HORMIGON CICLOPEO | O125: M3 | P125: 1 | Q125: 65.83
M126: 119 | N126: DEMOLICION DE HORMIGON CICLOPEO | O126: ML | P126: 1 | Q126: 5.55
M127: 120 | N127: DEMOLICION DE HORMIGON SIMPLE | O127: M3 | P127: 1 | Q127: 152.65
M128: 121 | N128: DEMOLICION DE HORMIGON, ELIMINACION CON TRANS. A 2 KM | O128: M3 | P128: 1 | Q128: 268.47
... M510: 503 | N510: ZOCALO PARA PISO VINILICOS | O510: ML | P510: 1 | Q510: 32.53
